Workbook

Sheet Tipy
A2: BODY
A3: PŘESNÉ SKÓRE ZÁPASU | F3: 15 | N3: PROCENTUÁLNÍ ÚSPĚŠNOST | S3: PROCENTUÁLNÍ ÚSPĚŠNOST | X3: PROCENTUÁLNÍ ÚSPĚŠNOST | AC3: PROCENTUÁLNÍ ÚSPĚŠNOST | AH3: PROCENTUÁLNÍ ÚSPĚŠNOST | AM3: PROCENTUÁLNÍ ÚSPĚŠNOST | AR3: PROCENTUÁLNÍ ÚSPĚŠNOST | AW3: PROCENTUÁLNÍ ÚSPĚŠNOST | BB3: PROCENTUÁLNÍ ÚSPĚŠNOST | BG3: PROCENTUÁLNÍ ÚSPĚŠNOST | BL3: PROCENTUÁLNÍ ÚSPĚŠNOST | BQ3: PROCENTUÁLNÍ ÚSPĚŠNOST
A4: REMÍZA BEZ PŘESNÉHO SKÓRE | F4: 8 | N4: =COUNTIF(N9:N25, ">0") / COUNTA(N9:N25) -> 0.375 | S4: =COUNTIF(S9:S25, ">0") / COUNTA(S9:S25) -> 0.4375 | X4: =COUNTIF(X9:X25, ">0") / COUNTA(X9:X25) -> 0.5 | AC4: =COUNTIF(AC9:AC25, ">0") / COUNTA(AC9:AC25) -> 0.5625 | AH4: =COUNTIF(AH9:AH25, ">0") / COUNTA(AH9:AH25) -> 0.4375 | AI4: =COUNTIF(AI9:AJ53, ">0") / COUNTA(AI9:AI53) -> #DIV/0! | AM4: =COUNTIF(AM9:AM25, ">0") / COUNTA(AM9:AM25) -> 0.375 | AN4: =COUNTIF(AN9:AO53, ">0") / COUNTA(AN9:AN53) -> #DIV/0! | AR4: =COUNTIF(AR9:AR25, ">0") / COUNTA(AR9:AR25) -> 0.5625 | AW4: =COUNTIF(AW9:AW25, ">0") / COUNTA(AW9:AW25) -> 0.375 | AX4: =COUNTIF(AX9:AY53, ">0") / COUNTA(AX9:AX53) -> #DIV/0! | BB4: =COUNTIF(BB9:BB25, ">0") / COUNTA(BB9:BB25) -> 0.5 | BC4: =COUNTIF(BC9:BD53, ">0") / COUNTA(BC9:BC53) -> #DIV/0! | BG4: =COUNTIF(BG9:BG25, ">0") / COUNTA(BG9:BG25) -> 0.5625 | BH4: =COUNTIF(BH9:BI53, ">0") / COUNTA(BH9:BH53) -> #DIV/0! | BL4: =COUNTIF(BL9:BL25, ">0") / COUNTA(BL9:BL25) -> 0.4375 | BM4: =COUNTIF(BM9:BN53, ">0") / COUNTA(BM9:BM53) -> #DIV/0! | BQ4: =COUNTIF(BQ9:BQ25, ">0") / COUNTA(BQ9:BQ25) -> 0.25
A5: POUZE VÍTĚZ | F5: 4
A6: VÍTĚZ ZÁPASU + ROZDÍL VE SKÓRE | F6: 6
A7: ŽOLÍK (ZDVOJNÁSOBÍ POČET VYHRANÝCH BODŮ, NUTNO OZNAČIT BAREVNĚ) | F7: 2x | N7: Jirka | S7: Kamil | X7: Martin | AC7: Filip | AH7: Pája | AM7: Vítek | AR7: Janička | AW7: Monča | BB7: Sláva | BG7: Tomáš | BL7: David | BQ7: Adam
A8: ŽOLÍK 1X KAŽDÉ ODEHRANÉ KOLO | H8: výsledek | N8: =SUM(N9:N53) -> 61 | S8: =SUM(S9:S53) -> 98 | X8: =SUM(X9:X53) -> 86 | AC8: =SUM(AC9:AC53) -> 110 | AH8: =SUM(AH9:AH53) -> 77 | AM8: =SUM(AM9:AM53) -> 71 | AR8: =SUM(AR9:AR53) -> 122 | AW8: =SUM(AW9:AW53) -> 61 | BB8: =SUM(BB9:BB53) -> 90 | BG8: =SUM(BG9:BG53) -> 96 | BL8: =SUM(BL9:BL53) -> 106 | BQ8: =SUM(BQ9:BQ53) -> 66
A9: sobota 25.7 | B9: 0.70833333 | C9: TEPLICE | D9: BOHEMIANS | E9: 1 .KOLO | G9: 3 | H9: : | I9: 1 | K9: 1 | L9: : | M9: 1 | N9: =IF(OR(G9="", I9="", K9="", M9=""), "", IF(AND(G9=K9, I9=M9), $F$3, IF(G9-I9=K9-M9, $F$4, IF(AND(G9=I9, K9=M9),$F$6, IF(SIGN(G9-I9)=SIGN(K9-M9), $F$5, 0))))) -> 0 | P9: 3 | Q9: : | R9: 0 | S9: =IF(OR(G9="", I9="", P9="", R9=""), "", IF(AND(G9=P9, I9=R9), $F$3, IF(G9-I9=P9-R9, $F$4, IF(AND(G9=I9, P9=R9),$F$6, IF(SIGN(G9-I9)=SIGN(P9-R9), $F$5, 0))))) -> 4 | U9: 2 | V9: : | W9: 1 | X9: =IF(OR(G9="", I9="", U9="", W9=""), "", IF(AND(G9=U9, I9=W9), $F$3, IF(G9-I9=U9-W9, $F$4, IF(AND(G9=I9, U9=W9),$F$6, IF(SIGN(G9-I9)=SIGN(U9-W9), $F$5, 0))))) -> 4 | Z9: 2 | AA9: : | AB9: 0 | AC9: 6 | AE9: 2 | AF9: : | AG9: 1 | AH9: =IF(OR(G9="", I9="", AE9="", AG9=""), "", IF(AND(G9=AE9, I9=AG9), $F$3, IF(G9-I9=AE9-AG9, $F$4, IF(AND(G9=I9, AE9=AG9),$F$6, IF(SIGN(G9-I9)=SIGN(AE9-AG9), $F$5, 0))))) -> 4 | AJ9: 2 | AK9: : | AL9: 1 | AM9: =IF(OR(G9="", I9="", AJ9="", AL9=""), "", IF(AND(G9=AJ9, I9=AL9), $F$3, IF(G9-I9=AJ9-AL9, $F$4, IF(AND(G9=I9, AJ9=AL9),$F$6, IF(SIGN(G9-I9)=SIGN(AJ9-AL9), $F$5, 0))))) -> 4 | AO9: 2 | AP9: : | AQ9: 0 | AR9: 6 | AT9: 1 | AU9: : | AV9: 1 | AW9: =IF(OR(G9="", I9="", AT9="", AV9=""), "", IF(AND(G9=AT9, I9=AV9), $F$3, IF(G9-I9=AT9-AV9, $F$4, IF(AND(G9=I9, AT9=AV9),$F$6, IF(SIGN(G9-I9)=SIGN(AT9-AV9), $F$5, 0))))) -> 0 | AY9: 1 | AZ9: : | BA9: 0 | BB9: =IF(OR(G9="", I9="", AY9="", BA9=""), "", IF(AND(G9=AY9, I9=BA9), $F$3, IF(G9-I9=AY9-BA9, $F$4, IF(AND(G9=I9, AY9=BA9),$F$6, IF(SIGN(G9-I9)=SIGN(AY9-BA9), $F$5, 0))))) -> 4 | BD9: 1 | BE9: : | BF9: 0 | BG9: =IF(OR(G9="", I9="", BD9="", BF9=""), "", IF(AND(G9=BD9, I9=BF9), $F$3, IF(G9-I9=BD9-BF9, $F$4, IF(AND(G9=I9, BD9=BF9),$F$6, IF(SIGN(G9-I9)=SIGN(BD9-BF9), $F$5, 0))))) -> 4 | BI9: 0 | BJ9: : | BK9: 0 | BL9: 0 | BO9: : | BQ9: =IF(OR(Q9="", S9="", BN9="", BP9=""), "", IF(AND(Q9=BN9, S9=BP9), $F$3, IF(Q9-S9=BN9-BP9, $F$4, IF(AND(Q9=S9, BN9=BP9),$F$6, IF(SIGN(Q9-S9)=SIGN(BN9-BP9), $F$5, 0)))))
A10: sobota 25.7 | B10: 0.70833333 | C10: PLZEŇ | D10: LIBEREC | G10: 1 | H10: : | I10: 3 | K10: 3 | L10: : | M10: 1 | N10: =IF(OR(G10="", I10="", K10="", M10=""), "", IF(AND(G10=K10, I10=M10), $F$3, IF(G10-I10=K10-M10, $F$4, IF(AND(G10=I10, K10=M10),$F$6, IF(SIGN(G10-I10)=SIGN(K10-M10), $F$5, 0))))) -> 0 | P10: 2 | Q10: : | R10: 1 | S10: =IF(OR(G10="", I10="", P10="", R10=""), "", IF(AND(G10=P10, I10=R10), $F$3, IF(G10-I10=P10-R10, $F$4, IF(AND(G10=I10, P10=R10),$F$6, IF(SIGN(G10-I10)=SIGN(P10-R10), $F$5, 0))))) -> 0 | U10: 2 | V10: : | W10: 0 | X10: =IF(OR(G10="", I10="", U10="", W10=""), "", IF(AND(G10=U10, I10=W10), $F$3, IF(G10-I10=U10-W10, $F$4, IF(AND(G10=I10, U10=W10),$F$6, IF(SIGN(G10-I10)=SIGN(U10-W10), $F$5, 0))))) -> 0 | Z10: 2 | AA10: : | AB10: 1 | AC10: =IF(OR(G10="", I10="", Z10="", AB10=""), "", IF(AND(G10=Z10, I10=AB10), $F$3, IF(G10-I10=Z10-AB10, $F$4, IF(AND(G10=I10, Z10=AB10),$F$6, IF(SIGN(G10-I10)=SIGN(Z10-AB10), $F$5, 0))))) -> 0 | AE10: 2 | AF10: : | AG10: 1 | AH10: =IF(OR(G10="", I10="", AE10="", AG10=""), "", IF(AND(G10=AE10, I10=AG10), $F$3, IF(G10-I10=AE10-AG10, $F$4, IF(AND(G10=I10, AE10=AG10),$F$6, IF(SIGN(G10-I10)=SIGN(AE10-AG10), $F$5, 0))))) -> 0 | AJ10: 3 | AK10: : | AL10: 1 | AM10: =IF(OR(G10="", I10="", AJ10="", AL10=""), "", IF(AND(G10=AJ10, I10=AL10), $F$3, IF(G10-I10=AJ10-AL10, $F$4, IF(AND(G10=I10, AJ10=AL10),$F$6, IF(SIGN(G10-I10)=SIGN(AJ10-AL10), $F$5, 0))))) -> 0 | AO10: 2 | AP10: : | AQ10: 1 | AR10: =IF(OR(G10="", I10="", AO10="", AQ10=""), "", IF(AND(G10=AO10, I10=AQ10), $F$3, IF(G10-I10=AO10-AQ10, $F$4, IF(AND(G10=I10, AO10=AQ10),$F$6, IF(SIGN(G10-I10)=SIGN(AO10-AQ10), $F$5, 0))))) -> 0 | AT10: 2 | AU10: : | AV10: 0 | AW10: =IF(OR(G10="", I10="", AT10="", AV10=""), "", IF(AND(G10=AT10, I10=AV10), $F$3, IF(G10-I10=AT10-AV10, $F$4, IF(AND(G10=I10, AT10=AV10),$F$6, IF(SIGN(G10-I10)=SIGN(AT10-AV10), $F$5, 0))))) -> 0 | AY10: 2 | AZ10: : | BA10: 2 | BB10: =IF(OR(G10="", I10="", AY10="", BA10=""), "", IF(AND(G10=AY10, I10=BA10), $F$3, IF(G10-I10=AY10-BA10, $F$4, IF(AND(G10=I10, AY10=BA10),$F$6, IF(SIGN(G10-I10)=SIGN(AY10-BA10), $F$5, 0))))) -> 0 | BD10: 2 | BE10: : | BF10: 1 | BG10: =IF(OR(G10="", I10="", BD10="", BF10=""), "", IF(AND(G10=BD10, I10=BF10), $F$3, IF(G10-I10=BD10-BF10, $F$4, IF(AND(G10=I10, BD10=BF10),$F$6, IF(SIGN(G10-I10)=SIGN(BD10-BF10), $F$5, 0))))) -> 0 | BI10: 2 | BJ10: : | BK10: 0 | BL10: 0 | BO10: : | BQ10: =IF(OR(Q10="", S10="", BN10="", BP10=""), "", IF(AND(Q10=BN10, S10=BP10), $F$3, IF(Q10-S10=BN10-BP10, $F$4, IF(AND(Q10=S10, BN10=BP10),$F$6, IF(SIGN(Q10-S10)=SIGN(BN10-BP10), $F$5, 0)))))
A11: sobota 25.7 | B11: 0.70833333 | C11: ZLÍN | D11: BANÍK OSTRAVA | G11: 0 | H11: : | I11: 1 | K11: 0 | L11: : | M11: 1 | N11: 15 | P11: 1 | Q11: : | R11: 1 | S11: =IF(OR(G11="", I11="", P11="", R11=""), "", IF(AND(G11=P11, I11=R11), $F$3, IF(G11-I11=P11-R11, $F$4, IF(AND(G11=I11, P11=R11),$F$6, IF(SIGN(G11-I11)=SIGN(P11-R11), $F$5, 0))))) -> 0 | U11: 1 | V11: : | W11: 3 | X11: =IF(OR(G11="", I11="", U11="", W11=""), "", IF(AND(G11=U11, I11=W11), $F$3, IF(G11-I11=U11-W11, $F$4, IF(AND(G11=I11, U11=W11),$F$6, IF(SIGN(G11-I11)=SIGN(U11-W11), $F$5, 0))))) -> 4 | Z11: 1 | AA11: : | AB11: 2 | AC11: 6 | AE11: 1 | AF11: : | AG11: 1 | AH11: =IF(OR(G11="", I11="", AE11="", AG11=""), "", IF(AND(G11=AE11, I11=AG11), $F$3, IF(G11-I11=AE11-AG11, $F$4, IF(AND(G11=I11, AE11=AG11),$F$6, IF(SIGN(G11-I11)=SIGN(AE11-AG11), $F$5, 0))))) -> 0 | AJ11: 1 | AK11: : | AL11: 0 | AM11: =IF(OR(G11="", I11="", AJ11="", AL11=""), "", IF(AND(G11=AJ11, I11=AL11), $F$3, IF(G11-I11=AJ11-AL11, $F$4, IF(AND(G11=I11, AJ11=AL11),$F$6, IF(SIGN(G11-I11)=SIGN(AJ11-AL11), $F$5, 0))))) -> 0 | AO11: 1 | AP11: : | AQ11: 1 | AR11: =IF(OR(G11="", I11="", AO11="", AQ11=""), "", IF(AND(G11=AO11, I11=AQ11), $F$3, IF(G11-I11=AO11-AQ11, $F$4, IF(AND(G11=I11, AO11=AQ11),$F$6, IF(SIGN(G11-I11)=SIGN(AO11-AQ11), $F$5, 0))))) -> 0 | AT11: 1 | AU11: : | AV11: 2 | AW11: 6 | AY11: 2 | AZ11: : | BA11: 0 | BB11: =IF(OR(G11="", I11="", AY11="", BA11=""), "", IF(AND(G11=AY11, I11=BA11), $F$3, IF(G11-I11=AY11-BA11, $F$4, IF(AND(G11=I11, AY11=BA11),$F$6, IF(SIGN(G11-I11)=SIGN(AY11-BA11), $F$5, 0))))) -> 0 | BD11: 1 | BE11: : | BF11: 1 | BG11: =IF(OR(G11="", I11="", BD11="", BF11=""), "", IF(AND(G11=BD11, I11=BF11), $F$3, IF(G11-I11=BD11-BF11, $F$4, IF(AND(G11=I11, BD11=BF11),$F$6, IF(SIGN(G11-I11)=SIGN(BD11-BF11), $F$5, 0))))) -> 0 | BI11: 0 | BJ11: : | BK11: 1 | BL11: 15 | BO11: : | BQ11: =IF(OR(Q11="", S11="", BN11="", BP11=""), "", IF(AND(Q11=BN11, S11=BP11), $F$3, IF(Q11-S11=BN11-BP11, $F$4, IF(AND(Q11=S11, BN11=BP11),$F$6, IF(SIGN(Q11-S11)=SIGN(BN11-BP11), $F$5, 0)))))
A12: sobota 25.7 | B12: 0.83333333 | C12: ZBROJOVKA BRNO | D12: SPARTA | G12: 3 | H12: : | I12: 1 | K12: 0 | L12: : | M12: 2 | N12: =IF(OR(G12="", I12="", K12="", M12=""), "", IF(AND(G12=K12, I12=M12), $F$3, IF(G12-I12=K12-M12, $F$4, IF(AND(G12=I12, K12=M12),$F$6, IF(SIGN(G12-I12)=SIGN(K12-M12), $F$5, 0))))) -> 0 | P12: 1 | Q12: : | R12: 1 | S12: =IF(OR(G12="", I12="", P12="", R12=""), "", IF(AND(G12=P12, I12=R12), $F$3, IF(G12-I12=P12-R12, $F$4, IF(AND(G12=I12, P12=R12),$F$6, IF(SIGN(G12-I12)=SIGN(P12-R12), $F$5, 0))))) -> 0 | U12: 0 | V12: : | W12: 3 | X12: =IF(OR(G12="", I12="", U12="", W12=""), "", IF(AND(G12=U12, I12=W12), $F$3, IF(G12-I12=U12-W12, $F$4, IF(AND(G12=I12, U12=W12),$F$6, IF(SIGN(G12-I12)=SIGN(U12-W12), $F$5, 0))))) -> 0 | Z12: 1 | AA12: : | AB12: 2 | AC12: =IF(OR(G12="", I12="", Z12="", AB12=""), "", IF(AND(G12=Z12, I12=AB12), $F$3, IF(G12-I12=Z12-AB12, $F$4, IF(AND(G12=I12, Z12=AB12),$F$6, IF(SIGN(G12-I12)=SIGN(Z12-AB12), $F$5, 0))))) -> 0 | AE12: 1 | AF12: : | AG12: 2 | AH12: =IF(OR(G12="", I12="", AE12="", AG12=""), "", IF(AND(G12=AE12, I12=AG12), $F$3, IF(G12-I12=AE12-AG12, $F$4, IF(AND(G12=I12, AE12=AG12),$F$6, IF(SIGN(G12-I12)=SIGN(AE12-AG12), $F$5, 0))))) -> 0 | AJ12: 1 | AK12: : | AL12: 2 | AM12: =IF(OR(G12="", I12="", AJ12="", AL12=""), "", IF(AND(G12=AJ12, I12=AL12), $F$3, IF(G12-I12=AJ12-AL12, $F$4, IF(AND(G12=I12, AJ12=AL12),$F$6, IF(SIGN(G12-I12)=SIGN(AJ12-AL12), $F$5, 0))))) -> 0 | AO12: 0 | AP12: : | AQ12: 2 | AR12: =IF(OR(G12="", I12="", AO12="", AQ12=""), "", IF(AND(G12=AO12, I12=AQ12), $F$3, IF(G12-I12=AO12-AQ12, $F$4, IF(AND(G12=I12, AO12=AQ12),$F$6, IF(SIGN(G12-I12)=SIGN(AO12-AQ12), $F$5, 0))))) -> 0 | AT12: 1 | AU12: : | AV12: 2 | AW12: =IF(OR(G12="", I12="", AT12="", AV12=""), "", IF(AND(G12=AT12, I12=AV12), $F$3, IF(G12-I12=AT12-AV12, $F$4, IF(AND(G12=I12, AT12=AV12),$F$6, IF(SIGN(G12-I12)=SIGN(AT12-AV12), $F$5, 0))))) -> 0 | AY12: 1 | AZ12: : | BA12: 2 | BB12: =IF(OR(G12="", I12="", AY12="", BA12=""), "", IF(AND(G12=AY12, I12=BA12), $F$3, IF(G12-I12=AY12-BA12, $F$4, IF(AND(G12=I12, AY12=BA12),$F$6, IF(SIGN(G12-I12)=SIGN(AY12-BA12), $F$5, 0))))) -> 0 | BD12: 1 | BE12: : | BF12: 2 | BG12: =IF(OR(G12="", I12="", BD12="", BF12=""), "", IF(AND(G12=BD12, I12=BF12), $F$3, IF(G12-I12=BD12-BF12, $F$4, IF(AND(G12=I12, BD12=BF12),$F$6, IF(SIGN(G12-I12)=SIGN(BD12-BF12), $F$5, 0))))) -> 0 | BI12: 0 | BJ12: : | BK12: 3 | BL12: 0 | BO12: : | BQ12: =IF(OR(Q12="", S12="", BN12="", BP12=""), "", IF(AND(Q12=BN12, S12=BP12), $F$3, IF(Q12-S12=BN12-BP12, $F$4, IF(AND(Q12=S12, BN12=BP12),$F$6, IF(SIGN(Q12-S12)=SIGN(BN12-BP12), $F$5, 0)))))
A13: neděle 26.7. | B13: 0.625 | C13: SLAVIA | D13: SLOVÁCKO | G13: 5 | H13: : | I13: 1 | K13: 3 | L13: : | M13: 0 | N13: 8 | P13: 4 | Q13: : | R13: 0 | S13: 12 | U13: 3 | V13: : | W13: 0 | X13: =IF(OR(G13="", I13="", U13="", W13=""), "", IF(AND(G13=U13, I13=W13), $F$3, IF(G13-I13=U13-W13, $F$4, IF(AND(G13=I13, U13=W13),$F$6, IF(SIGN(G13-I13)=SIGN(U13-W13), $F$5, 0))))) -> 4 | Z13: 3 | AA13: : | AB13: 0 | AC13: 8 | AE13: 2 | AF13: : | AG13: 0 | AH13: =IF(OR(G13="", I13="", AE13="", AG13=""), "", IF(AND(G13=AE13, I13=AG13), $F$3, IF(G13-I13=AE13-AG13, $F$4, IF(AND(G13=I13, AE13=AG13),$F$6, IF(SIGN(G13-I13)=SIGN(AE13-AG13), $F$5, 0))))) -> 4 | AJ13: 2 | AK13: : | AL13: 0 | AM13: 8 | AO13: 2 | AP13: : | AQ13: 1 | AR13: 8 | AT13: 2 | AU13: : | AV13: 0 | AW13: 8 | AY13: 3 | AZ13: : | BA13: 0 | BB13: 8 | BD13: 2 | BE13: : | BF13: 0 | BG13: 8 | BI13: 2 | BJ13: : | BK13: 1 | BL13: 8 | BO13: : | BQ13: =IF(OR(Q13="", S13="", BN13="", BP13=""), "", IF(AND(Q13=BN13, S13=BP13), $F$3, IF(Q13-S13=BN13-BP13, $F$4, IF(AND(Q13=S13, BN13=BP13),$F$6, IF(SIGN(Q13-S13)=SIGN(BN13-BP13), $F$5, 0)))))
A14: neděle 26.7. | B14: 0.72916667 | C14: JABLONEC | D14: OLOMOUC | G14: 2 | H14: : | I14: 1 | K14: 0 | L14: : | M14: 1 | N14: =IF(OR(G14="", I14="", K14="", M14=""), "", IF(AND(G14=K14, I14=M14), $F$3, IF(G14-I14=K14-M14, $F$4, IF(AND(G14=I14, K14=M14),$F$6, IF(SIGN(G14-I14)=SIGN(K14-M14), $F$5, 0))))) -> 0 | P14: 1 | Q14: : | R14: 2 | S14: =IF(OR(G14="", I14="", P14="", R14=""), "", IF(AND(G14=P14, I14=R14), $F$3, IF(G14-I14=P14-R14, $F$4, IF(AND(G14=I14, P14=R14),$F$6, IF(SIGN(G14-I14)=SIGN(P14-R14), $F$5, 0))))) -> 0 | U14: 1 | V14: : | W14: 1 | X14: =IF(OR(G14="", I14="", U14="", W14=""), "", IF(AND(G14=U14, I14=W14), $F$3, IF(G14-I14=U14-W14, $F$4, IF(AND(G14=I14, U14=W14),$F$6, IF(SIGN(G14-I14)=SIGN(U14-W14), $F$5, 0))))) -> 0 | Z14: 1 | AA14: : | AB14: 1 | AC14: =IF(OR(G14="", I14="", Z14="", AB14=""), "", IF(AND(G14=Z14, I14=AB14), $F$3, IF(G14-I14=Z14-AB14, $F$4, IF(AND(G14=I14, Z14=AB14),$F$6, IF(SIGN(G14-I14)=SIGN(Z14-AB14), $F$5, 0))))) -> 0 | AE14: 2 | AF14: : | AG14: 2 | AH14: =IF(OR(G14="", I14="", AE14="", AG14=""), "", IF(AND(G14=AE14, I14=AG14), $F$3, IF(G14-I14=AE14-AG14, $F$4, IF(AND(G14=I14, AE14=AG14),$F$6, IF(SIGN(G14-I14)=SIGN(AE14-AG14), $F$5, 0))))) -> 0 | AJ14: 1 | AK14: : | AL14: 1 | AM14: =IF(OR(G14="", I14="", AJ14="", AL14=""), "", IF(AND(G14=AJ14, I14=AL14), $F$3, IF(G14-I14=AJ14-AL14, $F$4, IF(AND(G14=I14, AJ14=AL14),$F$6, IF(SIGN(G14-I14)=SIGN(AJ14-AL14), $F$5, 0))))) -> 0 | AO14: 1 | AP14: : | AQ14: 0 | AR14: 6 | AT14: 1 | AU14: : | AV14: 1 | AW14: =IF(OR(G14="", I14="", AT14="", AV14=""), "", IF(AND(G14=AT14, I14=AV14), $F$3, IF(G14-I14=AT14-AV14, $F$4, IF(AND(G14=I14, AT14=AV14),$F$6, IF(SIGN(G14-I14)=SIGN(AT14-AV14), $F$5, 0))))) -> 0 | AY14: 1 | AZ14: : | BA14: 1 | BB14: =IF(OR(G14="", I14="", AY14="", BA14=""), "", IF(AND(G14=AY14, I14=BA14), $F$3, IF(G14-I14=AY14-BA14, $F$4, IF(AND(G14=I14, AY14=BA14),$F$6, IF(SIGN(G14-I14)=SIGN(AY14-BA14), $F$5, 0))))) -> 0 | BD14: 1 | BE14: : | BF14: 1 | BG14: =IF(OR(G14="", I14="", BD14="", BF14=""), "", IF(AND(G14=BD14, I14=BF14), $F$3, IF(G14-I14=BD14-BF14, $F$4, IF(AND(G14=I14, BD14=BF14),$F$6, IF(SIGN(G14-I14)=SIGN(BD14-BF14), $F$5, 0))))) -> 0 | BI14: 1 | BJ14: : | BK14: 3 | BL14: 0 | BO14: : | BQ14: =IF(OR(Q14="", S14="", BN14="", BP14=""), "", IF(AND(Q14=BN14, S14=BP14), $F$3, IF(Q14-S14=BN14-BP14, $F$4, IF(AND(Q14=S14, BN14=BP14),$F$6, IF(SIGN(Q14-S14)=SIGN(BN14-BP14), $F$5, 0)))))
A15: neděle 26.7. | B15: 0.83333333 | C15: HRADEC KRÁLOVÉ | D15: PARDUBICE | G15: 2 | H15: : | I15: 1 | K15: 1 | L15: : | M15: 1 | N15: =IF(OR(G15="", I15="", K15="", M15=""), "", IF(AND(G15=K15, I15=M15), $F$3, IF(G15-I15=K15-M15, $F$4, IF(AND(G15=I15, K15=M15),$F$6, IF(SIGN(G15-I15)=SIGN(K15-M15), $F$5, 0))))) -> 0 | P15: 1 | Q15: : | R15: 0 | S15: 6 | U15: 1 | V15: : | W15: 1 | X15: =IF(OR(G15="", I15="", U15="", W15=""), "", IF(AND(G15=U15, I15=W15), $F$3, IF(G15-I15=U15-W15, $F$4, IF(AND(G15=I15, U15=W15),$F$6, IF(SIGN(G15-I15)=SIGN(U15-W15), $F$5, 0))))) -> 0 | Z15: 2 | AA15: : | AB15: 1 | AC15: =IF(OR(G15="", I15="", Z15="", AB15=""), "", IF(AND(G15=Z15, I15=AB15), $F$3, IF(G15-I15=Z15-AB15, $F$4, IF(AND(G15=I15, Z15=AB15),$F$6, IF(SIGN(G15-I15)=SIGN(Z15-AB15), $F$5, 0))))) -> 15 | AE15: 2 | AF15: : | AG15: 1 | AH15: =IF(OR(G15="", I15="", AE15="", AG15=""), "", IF(AND(G15=AE15, I15=AG15), $F$3, IF(G15-I15=AE15-AG15, $F$4, IF(AND(G15=I15, AE15=AG15),$F$6, IF(SIGN(G15-I15)=SIGN(AE15-AG15), $F$5, 0))))) -> 15 | AJ15: 1 | AK15: : | AL15: 1 | AM15: =IF(OR(G15="", I15="", AJ15="", AL15=""), "", IF(AND(G15=AJ15, I15=AL15), $F$3, IF(G15-I15=AJ15-AL15, $F$4, IF(AND(G15=I15, AJ15=AL15),$F$6, IF(SIGN(G15-I15)=SIGN(AJ15-AL15), $F$5, 0))))) -> 0 | AO15: 2 | AP15: : | AQ15: 1 | AR15: =IF(OR(G15="", I15="", AO15="", AQ15=""), "", IF(AND(G15=AO15, I15=AQ15), $F$3, IF(G15-I15=AO15-AQ15, $F$4, IF(AND(G15=I15, AO15=AQ15),$F$6, IF(SIGN(G15-I15)=SIGN(AO15-AQ15), $F$5, 0))))) -> 15 | AT15: 2 | AU15: : | AV15: 1 | AW15: =IF(OR(G15="", I15="", AT15="", AV15=""), "", IF(AND(G15=AT15, I15=AV15), $F$3, IF(G15-I15=AT15-AV15, $F$4, IF(AND(G15=I15, AT15=AV15),$F$6, IF(SIGN(G15-I15)=SIGN(AT15-AV15), $F$5, 0))))) -> 15 | AY15: 2 | AZ15: : | BA15: 0 | BB15: =IF(OR(G15="", I15="", AY15="", BA15=""), "", IF(AND(G15=AY15, I15=BA15), $F$3, IF(G15-I15=AY15-BA15, $F$4, IF(AND(G15=I15, AY15=BA15),$F$6, IF(SIGN(G15-I15)=SIGN(AY15-BA15), $F$5, 0))))) -> 4 | BD15: 2 | BE15: : | BF15: 1 | BG15: =IF(OR(G15="", I15="", BD15="", BF15=""), "", IF(AND(G15=BD15, I15=BF15), $F$3, IF(G15-I15=BD15-BF15, $F$4, IF(AND(G15=I15, BD15=BF15),$F$6, IF(SIGN(G15-I15)=SIGN(BD15-BF15), $F$5, 0))))) -> 15 | BI15: 2 | BJ15: : | BK15: 2 | BL15: 0 | BO15: : | BQ15: =IF(OR(Q15="", S15="", BN15="", BP15=""), "", IF(AND(Q15=BN15, S15=BP15), $F$3, IF(Q15-S15=BN15-BP15, $F$4, IF(AND(Q15=S15, BN15=BP15),$F$6, IF(SIGN(Q15-S15)=SIGN(BN15-BP15), $F$5, 0)))))
A16: pondělí 27.7. | B16: 0.75 | C16: ARTIS BRNO | D16: MLADÁ BOLESLAV | G16: 2 | H16: : | I16: 4 | K16: 0 | L16: : | M16: 2 | N16: 6 | P16: 1 | Q16: : | R16: 1 | S16: =IF(OR(G16="", I16="", P16="", R16=""), "", IF(AND(G16=P16, I16=R16), $F$3, IF(G16-I16=P16-R16, $F$4, IF(AND(G16=I16, P16=R16),$F$6, IF(SIGN(G16-I16)=SIGN(P16-R16), $F$5, 0))))) -> 0 | U16: 0 | V16: : | W16: 2 | X16: 6 | Z16: 0 | AA16: : | AB16: 2 | AC16: 6 | AE16: 1 | AF16: : | AG16: 2 | AH16: =IF(OR(G16="", I16="", AE16="", AG16=""), "", IF(AND(G16=AE16, I16=AG16), $F$3, IF(G16-I16=AE16-AG16, $F$4, IF(AND(G16=I16, AE16=AG16),$F$6, IF(SIGN(G16-I16)=SIGN(AE16-AG16), $F$5, 0))))) -> 4 | AJ16: 0 | AK16: : | AL16: 2 | AM16: 6 | AO16: 0 | AP16: : | AQ16: 2 | AR16: 6 | AT16: 1 | AU16: : | AV16: 0 | AW16: =IF(OR(G16="", I16="", AT16="", AV16=""), "", IF(AND(G16=AT16, I16=AV16), $F$3, IF(G16-I16=AT16-AV16, $F$4, IF(AND(G16=I16, AT16=AV16),$F$6, IF(SIGN(G16-I16)=SIGN(AT16-AV16), $F$5, 0))))) -> 0 | AY16: 1 | AZ16: : | BA16: 2 | BB16: =IF(OR(G16="", I16="", AY16="", BA16=""), "", IF(AND(G16=AY16, I16=BA16), $F$3, IF(G16-I16=AY16-BA16, $F$4, IF(AND(G16=I16, AY16=BA16),$F$6, IF(SIGN(G16-I16)=SIGN(AY16-BA16), $F$5, 0))))) -> 4 | BD16: 1 | BE16: : | BF16: 3 | BG16: 6 | BI16: 0 | BJ16: : | BK16: 3 | BL16: 4 | BN16: 0 | BO16: : | BP16: 2 | BQ16: 12
A18: pátek 31.7 | B18: 0.79166667 | C18: SPARTA | D18: ZLÍN | E18: 2.KOLO | G18: 3 | H18: : | I18: 1 | K18: 2 | L18: : | M18: 0 | N18: 12 | P18: 4 | Q18: : | R18: 0 | S18: 8 | U18: 3 | V18: : | W18: 1 | X18: =IF(OR(G18="", I18="", U18="", W18=""), "", IF(AND(G18=U18, I18=W18), $F$3, IF(G18-I18=U18-W18, $F$4, IF(AND(G18=I18, U18=W18),$F$6, IF(SIGN(G18-I18)=SIGN(U18-W18), $F$5, 0))))) -> 15 | Z18: 3 | AA18: : | AB18: 0 | AC18: =IF(OR(G18="", I18="", Z18="", AB18=""), "", IF(AND(G18=Z18, I18=AB18), $F$3, IF(G18-I18=Z18-AB18, $F$4, IF(AND(G18=I18, Z18=AB18),$F$6, IF(SIGN(G18-I18)=SIGN(Z18-AB18), $F$5, 0))))) -> 4 | AE18: 2 | AF18: : | AG18: 0 | AH18: 12 | AJ18: 3 | AK18: : | AL18: 0 | AM18: 8 | AO18: 2 | AP18: : | AQ18: 0 | AR18: 6 | AT18: 3 | AU18: : | AV18: 0 | AW18: =IF(OR(G18="", I18="", AT18="", AV18=""), "", IF(AND(G18=AT18, I18=AV18), $F$3, IF(G18-I18=AT18-AV18, $F$4, IF(AND(G18=I18, AT18=AV18),$F$6, IF(SIGN(G18-I18)=SIGN(AT18-AV18), $F$5, 0))))) -> 4 | AY18: 2 | AZ18: : | BA18: 0 | BB18: 6 | BD18: 2 | BE18: : | BF18: 0 | BG18: 12 | BI18: 3 | BJ18: : | BK18: 0 | BL18: 4 | BN18: 2 | BO18: : | BP18: 0 | BQ18: 12
A19: sobota 1.8. | B19: 0.70833333 | C19: BANÍK OSTRAVA | D19: SLAVIA | G19: 0 | H19: : | I19: 4 | K19: 0 | L19: : | M19: 2 | N19: =IF(OR(G19="", I19="", K19="", M19=""), "", IF(AND(G19=K19, I19=M19), $F$3, IF(G19-I19=K19-M19, $F$4, IF(AND(G19=I19, K19=M19),$F$6, IF(SIGN(G19-I19)=SIGN(K19-M19), $F$5, 0))))) -> 4 | P19: 1 | Q19: : | R19: 3 | S19: =IF(OR(G19="", I19="", P19="", R19=""), "", IF(AND(G19=P19, I19=R19), $F$3, IF(G19-I19=P19-R19, $F$4, IF(AND(G19=I19, P19=R19),$F$6, IF(SIGN(G19-I19)=SIGN(P19-R19), $F$5, 0))))) -> 4 | U19: 0 | V19: : | W19: 3 | X19: 8 | Z19: 1 | AA19: : | AB19: 2 | AC19: =IF(OR(G19="", I19="", Z19="", AB19=""), "", IF(AND(G19=Z19, I19=AB19), $F$3, IF(G19-I19=Z19-AB19, $F$4, IF(AND(G19=I19, Z19=AB19),$F$6, IF(SIGN(G19-I19)=SIGN(Z19-AB19), $F$5, 0))))) -> 4 | AE19: 1 | AF19: : | AG19: 2 | AH19: =IF(OR(G19="", I19="", AE19="", AG19=""), "", IF(AND(G19=AE19, I19=AG19), $F$3, IF(G19-I19=AE19-AG19, $F$4, IF(AND(G19=I19, AE19=AG19),$F$6, IF(SIGN(G19-I19)=SIGN(AE19-AG19), $F$5, 0))))) -> 4 | AJ19: 1 | AK19: : | AL19: 3 | AM19: =IF(OR(G19="", I19="", AJ19="", AL19=""), "", IF(AND(G19=AJ19, I19=AL19), $F$3, IF(G19-I19=AJ19-AL19, $F$4, IF(AND(G19=I19, AJ19=AL19),$F$6, IF(SIGN(G19-I19)=SIGN(AJ19-AL19), $F$5, 0))))) -> 4 | AO19: 0 | AP19: : | AQ19: 3 | AR19: 8 | AT19: 1 | AU19: : | AV19: 2 | AW19: =IF(OR(G19="", I19="", AT19="", AV19=""), "", IF(AND(G19=AT19, I19=AV19), $F$3, IF(G19-I19=AT19-AV19, $F$4, IF(AND(G19=I19, AT19=AV19),$F$6, IF(SIGN(G19-I19)=SIGN(AT19-AV19), $F$5, 0))))) -> 4 | AY19: 0 | AZ19: : | BA19: 2 | BB19: 8 | BD19: 1 | BE19: : | BF19: 2 | BG19: =IF(OR(G19="", I19="", BD19="", BF19=""), "", IF(AND(G19=BD19, I19=BF19), $F$3, IF(G19-I19=BD19-BF19, $F$4, IF(AND(G19=I19, BD19=BF19),$F$6, IF(SIGN(G19-I19)=SIGN(BD19-BF19), $F$5, 0))))) -> 4 | BI19: 0 | BJ19: : | BK19: 2 | BL19: 4 | BN19: 1 | BO19: : | BP19: 2 | BQ19: 4
A20: sobota 1.8. | B20: 0.70833333 | C20: SLOVÁCKO | D20: ARTIS BRNO | G20: 1 | H20: : | I20: 1 | K20: 1 | L20: : | M20: 0 | N20: =IF(OR(G20="", I20="", K20="", M20=""), "", IF(AND(G20=K20, I20=M20), $F$3, IF(G20-I20=K20-M20, $F$4, IF(AND(G20=I20, K20=M20),$F$6, IF(SIGN(G20-I20)=SIGN(K20-M20), $F$5, 0))))) -> 0 | P20: 2 | Q20: : | R20: 2 | S20: =IF(OR(G20="", I20="", P20="", R20=""), "", IF(AND(G20=P20, I20=R20), $F$3, IF(G20-I20=P20-R20, $F$4, IF(AND(G20=I20, P20=R20),$F$6, IF(SIGN(G20-I20)=SIGN(P20-R20), $F$5, 0))))) -> 8 | U20: 2 | V20: : | W20: 1 | X20: =IF(OR(G20="", I20="", U20="", W20=""), "", IF(AND(G20=U20, I20=W20), $F$3, IF(G20-I20=U20-W20, $F$4, IF(AND(G20=I20, U20=W20),$F$6, IF(SIGN(G20-I20)=SIGN(U20-W20), $F$5, 0))))) -> 0 | Z20: 1 | AA20: : | AB20: 1 | AC20: =IF(OR(G20="", I20="", Z20="", AB20=""), "", IF(AND(G20=Z20, I20=AB20), $F$3, IF(G20-I20=Z20-AB20, $F$4, IF(AND(G20=I20, Z20=AB20),$F$6, IF(SIGN(G20-I20)=SIGN(Z20-AB20), $F$5, 0))))) -> 15 | AE20: 1 | AF20: : | AG20: 1 | AH20: =IF(OR(G20="", I20="", AE20="", AG20=""), "", IF(AND(G20=AE20, I20=AG20), $F$3, IF(G20-I20=AE20-AG20, $F$4, IF(AND(G20=I20, AE20=AG20),$F$6, IF(SIGN(G20-I20)=SIGN(AE20-AG20), $F$5, 0))))) -> 15 | AJ20: 2 | AK20: : | AL20: 1 | AM20: =IF(OR(G20="", I20="", AJ20="", AL20=""), "", IF(AND(G20=AJ20, I20=AL20), $F$3, IF(G20-I20=AJ20-AL20, $F$4, IF(AND(G20=I20, AJ20=AL20),$F$6, IF(SIGN(G20-I20)=SIGN(AJ20-AL20), $F$5, 0))))) -> 0 | AO20: 0 | AP20: : | AQ20: 1 | AR20: =IF(OR(G20="", I20="", AO20="", AQ20=""), "", IF(AND(G20=AO20, I20=AQ20), $F$3, IF(G20-I20=AO20-AQ20, $F$4, IF(AND(G20=I20, AO20=AQ20),$F$6, IF(SIGN(G20-I20)=SIGN(AO20-AQ20), $F$5, 0))))) -> 0 | AT20: 1 | AU20: : | AV20: 2 | AW20: =IF(OR(G20="", I20="", AT20="", AV20=""), "", IF(AND(G20=AT20, I20=AV20), $F$3, IF(G20-I20=AT20-AV20, $F$4, IF(AND(G20=I20, AT20=AV20),$F$6, IF(SIGN(G20-I20)=SIGN(AT20-AV20), $F$5, 0))))) -> 0 | AY20: 1 | AZ20: : | BA20: 1 | BB20: =IF(OR(G20="", I20="", AY20="", BA20=""), "", IF(AND(G20=AY20, I20=BA20), $F$3, IF(G20-I20=AY20-BA20, $F$4, IF(AND(G20=I20, AY20=BA20),$F$6, IF(SIGN(G20-I20)=SIGN(AY20-BA20), $F$5, 0))))) -> 15 | BD20: 1 | BE20: : | BF20: 1 | BG20: =IF(OR(G20="", I20="", BD20="", BF20=""), "", IF(AND(G20=BD20, I20=BF20), $F$3, IF(G20-I20=BD20-BF20, $F$4, IF(AND(G20=I20, BD20=BF20),$F$6, IF(SIGN(G20-I20)=SIGN(BD20-BF20), $F$5, 0))))) -> 15 | BI20: 1 | BJ20: : | BK20: 1 | BL20: 30 | BN20: 3 | BO20: : | BP20: 2 | BQ20: 0
A21: sobota 1.8. | B21: 0.70833333 | C21: LIBEREC | D21: TEPLICE | G21: 0 | H21: : | I21: 1 | K21: 2 | L21: : | M21: 0 | N21: =IF(OR(G21="", I21="", K21="", M21=""), "", IF(AND(G21=K21, I21=M21), $F$3, IF(G21-I21=K21-M21, $F$4, IF(AND(G21=I21, K21=M21),$F$6, IF(SIGN(G21-I21)=SIGN(K21-M21), $F$5, 0))))) -> 0 | P21: 2 | Q21: : | R21: 1 | S21: =IF(OR(G21="", I21="", P21="", R21=""), "", IF(AND(G21=P21, I21=R21), $F$3, IF(G21-I21=P21-R21, $F$4, IF(AND(G21=I21, P21=R21),$F$6, IF(SIGN(G21-I21)=SIGN(P21-R21), $F$5, 0))))) -> 0 | U21: 2 | V21: : | W21: 1 | X21: =IF(OR(G21="", I21="", U21="", W21=""), "", IF(AND(G21=U21, I21=W21), $F$3, IF(G21-I21=U21-W21, $F$4, IF(AND(G21=I21, U21=W21),$F$6, IF(SIGN(G21-I21)=SIGN(U21-W21), $F$5, 0))))) -> 0 | Z21: 2 | AA21: : | AB21: 0 | AC21: =IF(OR(G21="", I21="", Z21="", AB21=""), "", IF(AND(G21=Z21, I21=AB21), $F$3, IF(G21-I21=Z21-AB21, $F$4, IF(AND(G21=I21, Z21=AB21),$F$6, IF(SIGN(G21-I21)=SIGN(Z21-AB21), $F$5, 0))))) -> 0 | AE21: 2 | AF21: : | AG21: 1 | AH21: =IF(OR(G21="", I21="", AE21="", AG21=""), "", IF(AND(G21=AE21, I21=AG21), $F$3, IF(G21-I21=AE21-AG21, $F$4, IF(AND(G21=I21, AE21=AG21),$F$6, IF(SIGN(G21-I21)=SIGN(AE21-AG21), $F$5, 0))))) -> 0 | AJ21: 2 | AK21: : | AL21: 0 | AM21: =IF(OR(G21="", I21="", AJ21="", AL21=""), "", IF(AND(G21=AJ21, I21=AL21), $F$3, IF(G21-I21=AJ21-AL21, $F$4, IF(AND(G21=I21, AJ21=AL21),$F$6, IF(SIGN(G21-I21)=SIGN(AJ21-AL21), $F$5, 0))))) -> 0 | AO21: 2 | AP21: : | AQ21: 0 | AR21: =IF(OR(G21="", I21="", AO21="", AQ21=""), "", IF(AND(G21=AO21, I21=AQ21), $F$3, IF(G21-I21=AO21-AQ21, $F$4, IF(AND(G21=I21, AO21=AQ21),$F$6, IF(SIGN(G21-I21)=SIGN(AO21-AQ21), $F$5, 0))))) -> 0 | AT21: 2 | AU21: : | AV21: 1 | AW21: =IF(OR(G21="", I21="", AT21="", AV21=""), "", IF(AND(G21=AT21, I21=AV21), $F$3, IF(G21-I21=AT21-AV21, $F$4, IF(AND(G21=I21, AT21=AV21),$F$6, IF(SIGN(G21-I21)=SIGN(AT21-AV21), $F$5, 0))))) -> 0 | AY21: 2 | AZ21: : | BA21: 0 | BB21: =IF(OR(G21="", I21="", AY21="", BA21=""), "", IF(AND(G21=AY21, I21=BA21), $F$3, IF(G21-I21=AY21-BA21, $F$4, IF(AND(G21=I21, AY21=BA21),$F$6, IF(SIGN(G21-I21)=SIGN(AY21-BA21), $F$5, 0))))) -> 0 | BD21: 3 | BE21: : | BF21: 1 | BG21: =IF(OR(G21="", I21="", BD21="", BF21=""), "", IF(AND(G21=BD21, I21=BF21), $F$3, IF(G21-I21=BD21-BF21, $F$4, IF(AND(G21=I21, BD21=BF21),$F$6, IF(SIGN(G21-I21)=SIGN(BD21-BF21), $F$5, 0))))) -> 0 | BI21: 2 | BJ21: : | BK21: 2 | BL21: 0 | BN21: 1 | BO21: : | BP21: 0 | BQ21: 0
A22: sobota 1.8. | B22: 0.83333333 | C22: PLZEŇ | D22: ZBROJOVKA BRNO | G22: 1 | H22: : | I22: 1 | K22: 2 | L22: : | M22: 1 | N22: =IF(OR(G22="", I22="", K22="", M22=""), "", IF(AND(G22=K22, I22=M22), $F$3, IF(G22-I22=K22-M22, $F$4, IF(AND(G22=I22, K22=M22),$F$6, IF(SIGN(G22-I22)=SIGN(K22-M22), $F$5, 0))))) -> 0 | P22: 1 | Q22: : | R22: 1 | S22: =IF(OR(G22="", I22="", P22="", R22=""), "", IF(AND(G22=P22, I22=R22), $F$3, IF(G22-I22=P22-R22, $F$4, IF(AND(G22=I22, P22=R22),$F$6, IF(SIGN(G22-I22)=SIGN(P22-R22), $F$5, 0))))) -> 15 | U22: 2 | V22: : | W22: 2 | X22: =IF(OR(G22="", I22="", U22="", W22=""), "", IF(AND(G22=U22, I22=W22), $F$3, IF(G22-I22=U22-W22, $F$4, IF(AND(G22=I22, U22=W22),$F$6, IF(SIGN(G22-I22)=SIGN(U22-W22), $F$5, 0))))) -> 8 | Z22: 1 | AA22: : | AB22: 2 | AC22: =IF(OR(G22="", I22="", Z22="", AB22=""), "", IF(AND(G22=Z22, I22=AB22), $F$3, IF(G22-I22=Z22-AB22, $F$4, IF(AND(G22=I22, Z22=AB22),$F$6, IF(SIGN(G22-I22)=SIGN(Z22-AB22), $F$5, 0))))) -> 0 | AE22: 2 | AF22: : | AG22: 0 | AH22: =IF(OR(G22="", I22="", AE22="", AG22=""), "", IF(AND(G22=AE22, I22=AG22), $F$3, IF(G22-I22=AE22-AG22, $F$4, IF(AND(G22=I22, AE22=AG22),$F$6, IF(SIGN(G22-I22)=SIGN(AE22-AG22), $F$5, 0))))) -> 0 | AJ22: 2 | AK22: : | AL22: 1 | AM22: =IF(OR(G22="", I22="", AJ22="", AL22=""), "", IF(AND(G22=AJ22, I22=AL22), $F$3, IF(G22-I22=AJ22-AL22, $F$4, IF(AND(G22=I22, AJ22=AL22),$F$6, IF(SIGN(G22-I22)=SIGN(AJ22-AL22), $F$5, 0))))) -> 0 | AO22: 2 | AP22: : | AQ22: 1 | AR22: =IF(OR(G22="", I22="", AO22="", AQ22=""), "", IF(AND(G22=AO22, I22=AQ22), $F$3, IF(G22-I22=AO22-AQ22, $F$4, IF(AND(G22=I22, AO22=AQ22),$F$6, IF(SIGN(G22-I22)=SIGN(AO22-AQ22), $F$5, 0))))) -> 0 | AT22: 2 | AU22: : | AV22: 0 | AW22: =IF(OR(G22="", I22="", AT22="", AV22=""), "", IF(AND(G22=AT22, I22=AV22), $F$3, IF(G22-I22=AT22-AV22, $F$4, IF(AND(G22=I22, AT22=AV22),$F$6, IF(SIGN(G22-I22)=SIGN(AT22-AV22), $F$5, 0))))) -> 0 | AY22: 3 | AZ22: : | BA22: 1 | BB22: =IF(OR(G22="", I22="", AY22="", BA22=""), "", IF(AND(G22=AY22, I22=BA22), $F$3, IF(G22-I22=AY22-BA22, $F$4, IF(AND(G22=I22, AY22=BA22),$F$6, IF(SIGN(G22-I22)=SIGN(AY22-BA22), $F$5, 0))))) -> 0 | BD22: 2 | BE22: : | BF22: 2 | BG22: =IF(OR(G22="", I22="", BD22="", BF22=""), "", IF(AND(G22=BD22, I22=BF22), $F$3, IF(G22-I22=BD22-BF22, $F$4, IF(AND(G22=I22, BD22=BF22),$F$6, IF(SIGN(G22-I22)=SIGN(BD22-BF22), $F$5, 0))))) -> 8 | BI22: 2 | BJ22: : | BK22: 1 | BL22: 0 | BN22: 2 | BO22: : | BP22: 1 | BQ22: 0
A23: neděle 2.8. | B23: 0.625 | C23: OLOMOUC | D23: MLADÁ BOLESLAV | G23: 2 | H23: : | I23: 2 | K23: 1 | L23: : | M23: 1 | N23: =IF(OR(G23="", I23="", K23="", M23=""), "", IF(AND(G23=K23, I23=M23), $F$3, IF(G23-I23=K23-M23, $F$4, IF(AND(G23=I23, K23=M23),$F$6, IF(SIGN(G23-I23)=SIGN(K23-M23), $F$5, 0))))) -> 8 | P23: 2 | Q23: : | R23: 0 | S23: =IF(OR(G23="", I23="", P23="", R23=""), "", IF(AND(G23=P23, I23=R23), $F$3, IF(G23-I23=P23-R23, $F$4, IF(AND(G23=I23, P23=R23),$F$6, IF(SIGN(G23-I23)=SIGN(P23-R23), $F$5, 0))))) -> 0 | U23: 2 | V23: : | W23: 3 | X23: =IF(OR(G23="", I23="", U23="", W23=""), "", IF(AND(G23=U23, I23=W23), $F$3, IF(G23-I23=U23-W23, $F$4, IF(AND(G23=I23, U23=W23),$F$6, IF(SIGN(G23-I23)=SIGN(U23-W23), $F$5, 0))))) -> 0 | Z23: 2 | AA23: : | AB23: 1 | AC23: =IF(OR(G23="", I23="", Z23="", AB23=""), "", IF(AND(G23=Z23, I23=AB23), $F$3, IF(G23-I23=Z23-AB23, $F$4, IF(AND(G23=I23, Z23=AB23),$F$6, IF(SIGN(G23-I23)=SIGN(Z23-AB23), $F$5, 0))))) -> 0 | AE23: 1 | AF23: : | AG23: 2 | AH23: =IF(OR(G23="", I23="", AE23="", AG23=""), "", IF(AND(G23=AE23, I23=AG23), $F$3, IF(G23-I23=AE23-AG23, $F$4, IF(AND(G23=I23, AE23=AG23),$F$6, IF(SIGN(G23-I23)=SIGN(AE23-AG23), $F$5, 0))))) -> 0 | AJ23: 3 | AK23: : | AL23: 2 | AM23: =IF(OR(G23="", I23="", AJ23="", AL23=""), "", IF(AND(G23=AJ23, I23=AL23), $F$3, IF(G23-I23=AJ23-AL23, $F$4, IF(AND(G23=I23, AJ23=AL23),$F$6, IF(SIGN(G23-I23)=SIGN(AJ23-AL23), $F$5, 0))))) -> 0 | AO23: 2 | AP23: : | AQ23: 2 | AR23: =IF(OR(G23="", I23="", AO23="", AQ23=""), "", IF(AND(G23=AO23, I23=AQ23), $F$3, IF(G23-I23=AO23-AQ23, $F$4, IF(AND(G23=I23, AO23=AQ23),$F$6, IF(SIGN(G23-I23)=SIGN(AO23-AQ23), $F$5, 0))))) -> 15 | AT23: 2 | AU23: : | AV23: 1 | AW23: =IF(OR(G23="", I23="", AT23="", AV23=""), "", IF(AND(G23=AT23, I23=AV23), $F$3, IF(G23-I23=AT23-AV23, $F$4, IF(AND(G23=I23, AT23=AV23),$F$6, IF(SIGN(G23-I23)=SIGN(AT23-AV23), $F$5, 0))))) -> 0 | AY23: 2 | AZ23: : | BA23: 1 | BB23: =IF(OR(G23="", I23="", AY23="", BA23=""), "", IF(AND(G23=AY23, I23=BA23), $F$3, IF(G23-I23=AY23-BA23, $F$4, IF(AND(G23=I23, AY23=BA23),$F$6, IF(SIGN(G23-I23)=SIGN(AY23-BA23), $F$5, 0))))) -> 0 | BD23: 2 | BE23: : | BF23: 0 | BG23: =IF(OR(G23="", I23="", BD23="", BF23=""), "", IF(AND(G23=BD23, I23=BF23), $F$3, IF(G23-I23=BD23-BF23, $F$4, IF(AND(G23=I23, BD23=BF23),$F$6, IF(SIGN(G23-I23)=SIGN(BD23-BF23), $F$5, 0))))) -> 0 | BI23: 1 | BJ23: : | BK23: 3 | BL23: 0 | BN23: 1 | BO23: : | BP23: 0 | BQ23: 0
A24: neděle 2.8. | B24: 0.72916667 | C24: BOHEMIANS | D24: HRADEC KRÁLOVÉ | G24: 0 | H24: : | I24: 0 | K24: 0 | L24: : | M24: 2 | N24: =IF(OR(G24="", I24="", K24="", M24=""), "", IF(AND(G24=K24, I24=M24), $F$3, IF(G24-I24=K24-M24, $F$4, IF(AND(G24=I24, K24=M24),$F$6, IF(SIGN(G24-I24)=SIGN(K24-M24), $F$5, 0))))) -> 0 | P24: 1 | Q24: : | R24: 2 | S24: =IF(OR(G24="", I24="", P24="", R24=""), "", IF(AND(G24=P24, I24=R24), $F$3, IF(G24-I24=P24-R24, $F$4, IF(AND(G24=I24, P24=R24),$F$6, IF(SIGN(G24-I24)=SIGN(P24-R24), $F$5, 0))))) -> 0 | U24: 1 | V24: : | W24: 2 | X24: =IF(OR(G24="", I24="", U24="", W24=""), "", IF(AND(G24=U24, I24=W24), $F$3, IF(G24-I24=U24-W24, $F$4, IF(AND(G24=I24, U24=W24),$F$6, IF(SIGN(G24-I24)=SIGN(U24-W24), $F$5, 0))))) -> 0 | Z24: 0 | AA24: : | AB24: 1 | AC24: =IF(OR(G24="", I24="", Z24="", AB24=""), "", IF(AND(G24=Z24, I24=AB24), $F$3, IF(G24-I24=Z24-AB24, $F$4, IF(AND(G24=I24, Z24=AB24),$F$6, IF(SIGN(G24-I24)=SIGN(Z24-AB24), $F$5, 0))))) -> 0 | AE24: 1 | AF24: : | AG24: 3 | AH24: =IF(OR(G24="", I24="", AE24="", AG24=""), "", IF(AND(G24=AE24, I24=AG24), $F$3, IF(G24-I24=AE24-AG24, $F$4, IF(AND(G24=I24, AE24=AG24),$F$6, IF(SIGN(G24-I24)=SIGN(AE24-AG24), $F$5, 0))))) -> 0 | AJ24: 1 | AK24: : | AL24: 1 | AM24: =IF(OR(G24="", I24="", AJ24="", AL24=""), "", IF(AND(G24=AJ24, I24=AL24), $F$3, IF(G24-I24=AJ24-AL24, $F$4, IF(AND(G24=I24, AJ24=AL24),$F$6, IF(SIGN(G24-I24)=SIGN(AJ24-AL24), $F$5, 0))))) -> 8 | AO24: 1 | AP24: : | AQ24: 2 | AR24: =IF(OR(G24="", I24="", AO24="", AQ24=""), "", IF(AND(G24=AO24, I24=AQ24), $F$3, IF(G24-I24=AO24-AQ24, $F$4, IF(AND(G24=I24, AO24=AQ24),$F$6, IF(SIGN(G24-I24)=SIGN(AO24-AQ24), $F$5, 0))))) -> 0 | AT24: 1 | AU24: : | AV24: 2 | AW24: =IF(OR(G24="", I24="", AT24="", AV24=""), "", IF(AND(G24=AT24, I24=AV24), $F$3, IF(G24-I24=AT24-AV24, $F$4, IF(AND(G24=I24, AT24=AV24),$F$6, IF(SIGN(G24-I24)=SIGN(AT24-AV24), $F$5, 0))))) -> 0 | AY24: 0 | AZ24: : | BA24: 2 | BB24: =IF(OR(G24="", I24="", AY24="", BA24=""), "", IF(AND(G24=AY24, I24=BA24), $F$3, IF(G24-I24=AY24-BA24, $F$4, IF(AND(G24=I24, AY24=BA24),$F$6, IF(SIGN(G24-I24)=SIGN(AY24-BA24), $F$5, 0))))) -> 0 | BD24: 1 | BE24: : | BF24: 2 | BG24: =IF(OR(G24="", I24="", BD24="", BF24=""), "", IF(AND(G24=BD24, I24=BF24), $F$3, IF(G24-I24=BD24-BF24, $F$4, IF(AND(G24=I24, BD24=BF24),$F$6, IF(SIGN(G24-I24)=SIGN(BD24-BF24), $F$5, 0))))) -> 0 | BI24: 1 | BJ24: : | BK24: 2 | BL24: 0 | BN24: 0 | BO24: : | BP24: 0 | BQ24: 15
A25: neděle 2.8. | B25: 0.83333333 | C25: PARDUBICE | D25: JABLONEC | G25: 0 | H25: : | I25: 2 | K25: 1 | L25: : | M25: 1 | N25: =IF(OR(G25="", I25="", K25="", M25=""), "", IF(AND(G25=K25, I25=M25), $F$3, IF(G25-I25=K25-M25, $F$4, IF(AND(G25=I25, K25=M25),$F$6, IF(SIGN(G25-I25)=SIGN(K25-M25), $F$5, 0))))) -> 0 | P25: 1 | Q25: : | R25: 1 | S25: =IF(OR(G25="", I25="", P25="", R25=""), "", IF(AND(G25=P25, I25=R25), $F$3, IF(G25-I25=P25-R25, $F$4, IF(AND(G25=I25, P25=R25),$F$6, IF(SIGN(G25-I25)=SIGN(P25-R25), $F$5, 0))))) -> 0 | U25: 0 | V25: : | W25: 2 | X25: =IF(OR(G25="", I25="", U25="", W25=""), "", IF(AND(G25=U25, I25=W25), $F$3, IF(G25-I25=U25-W25, $F$4, IF(AND(G25=I25, U25=W25),$F$6, IF(SIGN(G25-I25)=SIGN(U25-W25), $F$5, 0))))) -> 15 | Z25: 1 | AA25: : | AB25: 2 | AC25: =IF(OR(G25="", I25="", Z25="", AB25=""), "", IF(AND(G25=Z25, I25=AB25), $F$3, IF(G25-I25=Z25-AB25, $F$4, IF(AND(G25=I25, Z25=AB25),$F$6, IF(SIGN(G25-I25)=SIGN(Z25-AB25), $F$5, 0))))) -> 4 | AE25: 2 | AF25: : | AG25: 1 | AH25: =IF(OR(G25="", I25="", AE25="", AG25=""), "", IF(AND(G25=AE25, I25=AG25), $F$3, IF(G25-I25=AE25-AG25, $F$4, IF(AND(G25=I25, AE25=AG25),$F$6, IF(SIGN(G25-I25)=SIGN(AE25-AG25), $F$5, 0))))) -> 0 | AJ25: 2 | AK25: : | AL25: 1 | AM25: =IF(OR(G25="", I25="", AJ25="", AL25=""), "", IF(AND(G25=AJ25, I25=AL25), $F$3, IF(G25-I25=AJ25-AL25, $F$4, IF(AND(G25=I25, AJ25=AL25),$F$6, IF(SIGN(G25-I25)=SIGN(AJ25-AL25), $F$5, 0))))) -> 0 | AO25: 1 | AP25: : | AQ25: 2 | AR25: =IF(OR(G25="", I25="", AO25="", AQ25=""), "", IF(AND(G25=AO25, I25=AQ25), $F$3, IF(G25-I25=AO25-AQ25, $F$4, IF(AND(G25=I25, AO25=AQ25),$F$6, IF(SIGN(G25-I25)=SIGN(AO25-AQ25), $F$5, 0))))) -> 4 | AT25: 1 | AU25: : | AV25: 2 | AW25: =IF(OR(G25="", I25="", AT25="", AV25=""), "", IF(AND(G25=AT25, I25=AV25), $F$3, IF(G25-I25=AT25-AV25, $F$4, IF(AND(G25=I25, AT25=AV25),$F$6, IF(SIGN(G25-I25)=SIGN(AT25-AV25), $F$5, 0))))) -> 4 | AY25: 1 | AZ25: : | BA25: 2 | BB25: =IF(OR(G25="", I25="", AY25="", BA25=""), "", IF(AND(G25=AY25, I25=BA25), $F$3, IF(G25-I25=AY25-BA25, $F$4, IF(AND(G25=I25, AY25=BA25),$F$6, IF(SIGN(G25-I25)=SIGN(AY25-BA25), $F$5, 0))))) -> 4 | BD25: 0 | BE25: : | BF25: 1 | BG25: =IF(OR(G25="", I25="", BD25="", BF25=""), "", IF(AND(G25=BD25, I25=BF25), $F$3, IF(G25-I25=BD25-BF25, $F$4, IF(AND(G25=I25, BD25=BF25),$F$6, IF(SIGN(G25-I25)=SIGN(BD25-BF25), $F$5, 0))))) -> 4 | BI25: 0 | BJ25: : | BK25: 2 | BL25: 15 | BN25: 1 | BO25: : | BP25: 0 | BQ25: 0
A27: pátek 7.8. | B27: 0.79166667 | C27: ZBROJOVKA BRNO | D27: LIBEREC | E27: 3.KOLO | G27: 0 | H27: : | I27: 1 | K27: 1 | L27: : | M27: 1 | N27: =IF(OR(G27="", I27="", K27="", M27=""), "", IF(AND(G27=K27, I27=M27), $F$3, IF(G27-I27=K27-M27, $F$4, IF(AND(G27=I27, K27=M27),$F$6, IF(SIGN(G27-I27)=SIGN(K27-M27), $F$5, 0))))) -> 0 | P27: 2 | Q27: : | R27: 1 | S27: =IF(OR(G27="", I27="", P27="", R27=""), "", IF(AND(G27=P27, I27=R27), $F$3, IF(G27-I27=P27-R27, $F$4, IF(AND(G27=I27, P27=R27),$F$6, IF(SIGN(G27-I27)=SIGN(P27-R27), $F$5, 0))))) -> 0 | U27: 2 | V27: : | W27: 1 | X27: =IF(OR(G27="", I27="", U27="", W27=""), "", IF(AND(G27=U27, I27=W27), $F$3, IF(G27-I27=U27-W27, $F$4, IF(AND(G27=I27, U27=W27),$F$6, IF(SIGN(G27-I27)=SIGN(U27-W27), $F$5, 0))))) -> 0 | Z27: 2 | AA27: : | AB27: 1 | AC27: =IF(OR(G27="", I27="", Z27="", AB27=""), "", IF(AND(G27=Z27, I27=AB27), $F$3, IF(G27-I27=Z27-AB27, $F$4, IF(AND(G27=I27, Z27=AB27),$F$6, IF(SIGN(G27-I27)=SIGN(Z27-AB27), $F$5, 0))))) -> 0 | AE27: 2 | AF27: : | AG27: 1 | AH27: =IF(OR(G27="", I27="", AE27="", AG27=""), "", IF(AND(G27=AE27, I27=AG27), $F$3, IF(G27-I27=AE27-AG27, $F$4, IF(AND(G27=I27, AE27=AG27),$F$6, IF(SIGN(G27-I27)=SIGN(AE27-AG27), $F$5, 0))))) -> 0 | AJ27: 1 | AK27: : | AL27: 1 | AM27: =IF(OR(G27="", I27="", AJ27="", AL27=""), "", IF(AND(G27=AJ27, I27=AL27), $F$3, IF(G27-I27=AJ27-AL27, $F$4, IF(AND(G27=I27, AJ27=AL27),$F$6, IF(SIGN(G27-I27)=SIGN(AJ27-AL27), $F$5, 0))))) -> 0 | AO27: 1 | AP27: : | AQ27: 1 | AR27: =IF(OR(G27="", I27="", AO27="", AQ27=""), "", IF(AND(G27=AO27, I27=AQ27), $F$3, IF(G27-I27=AO27-AQ27, $F$4, IF(AND(G27=I27, AO27=AQ27),$F$6, IF(SIGN(G27-I27)=SIGN(AO27-AQ27), $F$5, 0))))) -> 0 | AT27: 1 | AU27: : | AV27: 1 | AW27: =IF(OR(G27="", I27="", AT27="", AV27=""), "", IF(AND(G27=AT27, I27=AV27), $F$3, IF(G27-I27=AT27-AV27, $F$4, IF(AND(G27=I27, AT27=AV27),$F$6, IF(SIGN(G27-I27)=SIGN(AT27-AV27), $F$5, 0))))) -> 0 | AY27: 2 | AZ27: : | BA27: 3 | BB27: 6 | BD27: 2 | BE27: : | BF27: 1 | BG27: =IF(OR(G27="", I27="", BD27="", BF27=""), "", IF(AND(G27=BD27, I27=BF27), $F$3, IF(G27-I27=BD27-BF27, $F$4, IF(AND(G27=I27, BD27=BF27),$F$6, IF(SIGN(G27-I27)=SIGN(BD27-BF27), $F$5, 0))))) -> 0 | BI27: 1 | BJ27: : | BK27: 1 | BL27: 0 | BN27: 2 | BO27: : | BP27: 1 | BQ27: 0
A28: sobota 8.8. | B28: 0.70833333 | C28: TEPLICE | D28: PLZEŇ | G28: 5 | H28: : | I28: 5 | K28: 0 | L28: : | M28: 2 | N28: =IF(OR(G28="", I28="", K28="", M28=""), "", IF(AND(G28=K28, I28=M28), $F$3, IF(G28-I28=K28-M28, $F$4, IF(AND(G28=I28, K28=M28),$F$6, IF(SIGN(G28-I28)=SIGN(K28-M28), $F$5, 0))))) -> 0 | P28: 1 | Q28: : | R28: 1 | S28: =IF(OR(G28="", I28="", P28="", R28=""), "", IF(AND(G28=P28, I28=R28), $F$3, IF(G28-I28=P28-R28, $F$4, IF(AND(G28=I28, P28=R28),$F$6, IF(SIGN(G28-I28)=SIGN(P28-R28), $F$5, 0))))) -> 8 | U28: 0 | V28: : | W28: 1 | X28: =IF(OR(G28="", I28="", U28="", W28=""), "", IF(AND(G28=U28, I28=W28), $F$3, IF(G28-I28=U28-W28, $F$4, IF(AND(G28=I28, U28=W28),$F$6, IF(SIGN(G28-I28)=SIGN(U28-W28), $F$5, 0))))) -> 0 | Z28: 1 | AA28: : | AB28: 3 | AC28: =IF(OR(G28="", I28="", Z28="", AB28=""), "", IF(AND(G28=Z28, I28=AB28), $F$3, IF(G28-I28=Z28-AB28, $F$4, IF(AND(G28=I28, Z28=AB28),$F$6, IF(SIGN(G28-I28)=SIGN(Z28-AB28), $F$5, 0))))) -> 0 | AE28: 1 | AF28: : | AG28: 2 | AH28: =IF(OR(G28="", I28="", AE28="", AG28=""), "", IF(AND(G28=AE28, I28=AG28), $F$3, IF(G28-I28=AE28-AG28, $F$4, IF(AND(G28=I28, AE28=AG28),$F$6, IF(SIGN(G28-I28)=SIGN(AE28-AG28), $F$5, 0))))) -> 0 | AJ28: 1 | AK28: : | AL28: 3 | AM28: =IF(OR(G28="", I28="", AJ28="", AL28=""), "", IF(AND(G28=AJ28, I28=AL28), $F$3, IF(G28-I28=AJ28-AL28, $F$4, IF(AND(G28=I28, AJ28=AL28),$F$6, IF(SIGN(G28-I28)=SIGN(AJ28-AL28), $F$5, 0))))) -> 0 | AO28: 2 | AP28: : | AQ28: 1 | AR28: =IF(OR(G28="", I28="", AO28="", AQ28=""), "", IF(AND(G28=AO28, I28=AQ28), $F$3, IF(G28-I28=AO28-AQ28, $F$4, IF(AND(G28=I28, AO28=AQ28),$F$6, IF(SIGN(G28-I28)=SIGN(AO28-AQ28), $F$5, 0))))) -> 0 | AT28: 1 | AU28: : | AV28: 1 | AW28: 8 | AY28: 1 | AZ28: : | BA28: 2 | BB28: =IF(OR(G28="", I28="", AY28="", BA28=""), "", IF(AND(G28=AY28, I28=BA28), $F$3, IF(G28-I28=AY28-BA28, $F$4, IF(AND(G28=I28, AY28=BA28),$F$6, IF(SIGN(G28-I28)=SIGN(AY28-BA28), $F$5, 0))))) -> 0 | BD28: 1 | BE28: : | BF28: 2 | BG28: =IF(OR(G28="", I28="", BD28="", BF28=""), "", IF(AND(G28=BD28, I28=BF28), $F$3, IF(G28-I28=BD28-BF28, $F$4, IF(AND(G28=I28, BD28=BF28),$F$6, IF(SIGN(G28-I28)=SIGN(BD28-BF28), $F$5, 0))))) -> 0 | BI28: 1 | BJ28: : | BK28: 2 | BL28: 0 | BN28: 0 | BO28: : | BP28: 2 | BQ28: 0
A29: sobota 8.8. | B29: 0.70833333 | C29: ZLÍN | D29: BOHEMIANS | G29: 0 | H29: : | I29: 2 | K29: 1 | L29: : | M29: 1 | N29: =IF(OR(G29="", I29="", K29="", M29=""), "", IF(AND(G29=K29, I29=M29), $F$3, IF(G29-I29=K29-M29, $F$4, IF(AND(G29=I29, K29=M29),$F$6, IF(SIGN(G29-I29)=SIGN(K29-M29), $F$5, 0))))) -> 0 | P29: 1 | Q29: : | R29: 1 | S29: =IF(OR(G29="", I29="", P29="", R29=""), "", IF(AND(G29=P29, I29=R29), $F$3, IF(G29-I29=P29-R29, $F$4, IF(AND(G29=I29, P29=R29),$F$6, IF(SIGN(G29-I29)=SIGN(P29-R29), $F$5, 0))))) -> 0 | U29: 1 | V29: : | W29: 1 | X29: =IF(OR(G29="", I29="", U29="", W29=""), "", IF(AND(G29=U29, I29=W29), $F$3, IF(G29-I29=U29-W29, $F$4, IF(AND(G29=I29, U29=W29),$F$6, IF(SIGN(G29-I29)=SIGN(U29-W29), $F$5, 0))))) -> 0 | Z29: 1 | AA29: : | AB29: 1 | AC29: =IF(OR(G29="", I29="", Z29="", AB29=""), "", IF(AND(G29=Z29, I29=AB29), $F$3, IF(G29-I29=Z29-AB29, $F$4, IF(AND(G29=I29, Z29=AB29),$F$6, IF(SIGN(G29-I29)=SIGN(Z29-AB29), $F$5, 0))))) -> 0 | AE29: 2 | AF29: : | AG29: 1 | AH29: =IF(OR(G29="", I29="", AE29="", AG29=""), "", IF(AND(G29=AE29, I29=AG29), $F$3, IF(G29-I29=AE29-AG29, $F$4, IF(AND(G29=I29, AE29=AG29),$F$6, IF(SIGN(G29-I29)=SIGN(AE29-AG29), $F$5, 0))))) -> 0 | AJ29: 1 | AK29: : | AL29: 0 | AM29: =IF(OR(G29="", I29="", AJ29="", AL29=""), "", IF(AND(G29=AJ29, I29=AL29), $F$3, IF(G29-I29=AJ29-AL29, $F$4, IF(AND(G29=I29, AJ29=AL29),$F$6, IF(SIGN(G29-I29)=SIGN(AJ29-AL29), $F$5, 0))))) -> 0 | AO29: 0 | AP29: : | AQ29: 1 | AR29: =IF(OR(G29="", I29="", AO29="", AQ29=""), "", IF(AND(G29=AO29, I29=AQ29), $F$3, IF(G29-I29=AO29-AQ29, $F$4, IF(AND(G29=I29, AO29=AQ29),$F$6, IF(SIGN(G29-I29)=SIGN(AO29-AQ29), $F$5, 0))))) -> 4 | AT29: 1 | AU29: : | AV29: 1 | AW29: =IF(OR(G29="", I29="", AT29="", AV29=""), "", IF(AND(G29=AT29, I29=AV29), $F$3, IF(G29-I29=AT29-AV29, $F$4, IF(AND(G29=I29, AT29=AV29),$F$6, IF(SIGN(G29-I29)=SIGN(AT29-AV29), $F$5, 0))))) -> 0 | AY29: 0 | AZ29: : | BA29: 1 | BB29: =IF(OR(G29="", I29="", AY29="", BA29=""), "", IF(AND(G29=AY29, I29=BA29), $F$3, IF(G29-I29=AY29-BA29, $F$4, IF(AND(G29=I29, AY29=BA29),$F$6, IF(SIGN(G29-I29)=SIGN(AY29-BA29), $F$5, 0))))) -> 4 | BD29: 1 | BE29: : | BF29: 1 | BG29: =IF(OR(G29="", I29="", BD29="", BF29=""), "", IF(AND(G29=BD29, I29=BF29), $F$3, IF(G29-I29=BD29-BF29, $F$4, IF(AND(G29=I29, BD29=BF29),$F$6, IF(SIGN(G29-I29)=SIGN(BD29-BF29), $F$5, 0))))) -> 0 | BI29: 1 | BJ29: : | BK29: 2 | BL29: 4 | BN29: 1 | BO29: : | BP29: 1 | BQ29: 0
A30: sobota 8.8. | B30: 0.83333333 | C30: MLADÁ BOLESLAV | D30: SPARTA | G30: 2 | H30: : | I30: 0 | K30: 1 | L30: : | M30: 3 | N30: =IF(OR(G30="", I30="", K30="", M30=""), "", IF(AND(G30=K30, I30=M30), $F$3, IF(G30-I30=K30-M30, $F$4, IF(AND(G30=I30, K30=M30),$F$6, IF(SIGN(G30-I30)=SIGN(K30-M30), $F$5, 0))))) -> 0 | P30: 2 | Q30: : | R30: 4 | S30: =IF(OR(G30="", I30="", P30="", R30=""), "", IF(AND(G30=P30, I30=R30), $F$3, IF(G30-I30=P30-R30, $F$4, IF(AND(G30=I30, P30=R30),$F$6, IF(SIGN(G30-I30)=SIGN(P30-R30), $F$5, 0))))) -> 0 | U30: 2 | V30: : | W30: 3 | X30: =IF(OR(G30="", I30="", U30="", W30=""), "", IF(AND(G30=U30, I30=W30), $F$3, IF(G30-I30=U30-W30, $F$4, IF(AND(G30=I30, U30=W30),$F$6, IF(SIGN(G30-I30)=SIGN(U30-W30), $F$5, 0))))) -> 0 | Z30: 1 | AA30: : | AB30: 3 | AC30: =IF(OR(G30="", I30="", Z30="", AB30=""), "", IF(AND(G30=Z30, I30=AB30), $F$3, IF(G30-I30=Z30-AB30, $F$4, IF(AND(G30=I30, Z30=AB30),$F$6, IF(SIGN(G30-I30)=SIGN(Z30-AB30), $F$5, 0))))) -> 0 | AE30: 1 | AF30: : | AG30: 2 | AH30: =IF(OR(G30="", I30="", AE30="", AG30=""), "", IF(AND(G30=AE30, I30=AG30), $F$3, IF(G30-I30=AE30-AG30, $F$4, IF(AND(G30=I30, AE30=AG30),$F$6, IF(SIGN(G30-I30)=SIGN(AE30-AG30), $F$5, 0))))) -> 0 | AJ30: 1 | AK30: : | AL30: 3 | AM30: =IF(OR(G30="", I30="", AJ30="", AL30=""), "", IF(AND(G30=AJ30, I30=AL30), $F$3, IF(G30-I30=AJ30-AL30, $F$4, IF(AND(G30=I30, AJ30=AL30),$F$6, IF(SIGN(G30-I30)=SIGN(AJ30-AL30), $F$5, 0))))) -> 0 | AO30: 2 | AP30: : | AQ30: 3 | AR30: =IF(OR(G30="", I30="", AO30="", AQ30=""), "", IF(AND(G30=AO30, I30=AQ30), $F$3, IF(G30-I30=AO30-AQ30, $F$4, IF(AND(G30=I30, AO30=AQ30),$F$6, IF(SIGN(G30-I30)=SIGN(AO30-AQ30), $F$5, 0))))) -> 0 | AT30: 1 | AU30: : | AV30: 2 | AW30: =IF(OR(G30="", I30="", AT30="", AV30=""), "", IF(AND(G30=AT30, I30=AV30), $F$3, IF(G30-I30=AT30-AV30, $F$4, IF(AND(G30=I30, AT30=AV30),$F$6, IF(SIGN(G30-I30)=SIGN(AT30-AV30), $F$5, 0))))) -> 0 | AY30: 1 | AZ30: : | BA30: 2 | BB30: =IF(OR(G30="", I30="", AY30="", BA30=""), "", IF(AND(G30=AY30, I30=BA30), $F$3, IF(G30-I30=AY30-BA30, $F$4, IF(AND(G30=I30, AY30=BA30),$F$6, IF(SIGN(G30-I30)=SIGN(AY30-BA30), $F$5, 0))))) -> 0 | BD30: 0 | BE30: : | BF30: 2 | BG30: =IF(OR(G30="", I30="", BD30="", BF30=""), "", IF(AND(G30=BD30, I30=BF30), $F$3, IF(G30-I30=BD30-BF30, $F$4, IF(AND(G30=I30, BD30=BF30),$F$6, IF(SIGN(G30-I30)=SIGN(BD30-BF30), $F$5, 0))))) -> 0 | BI30: 0 | BJ30: : | BK30: 2 | BL30: 0 | BN30: 0 | BO30: : | BP30: 2 | BQ30: 0
A31: neděle 9.8. | B31: 0.625 | C31: SLAVIA | D31: PARDUBICE | G31: 2 | H31: : | I31: 1 | K31: 4 | L31: : | M31: 0 | N31: =IF(OR(G31="", I31="", K31="", M31=""), "", IF(AND(G31=K31, I31=M31), $F$3, IF(G31-I31=K31-M31, $F$4, IF(AND(G31=I31, K31=M31),$F$6, IF(SIGN(G31-I31)=SIGN(K31-M31), $F$5, 0))))) -> 4 | P31: 4 | Q31: : | R31: 0 | S31: 8 | U31: 4 | V31: : | W31: 0 | X31: =IF(OR(G31="", I31="", U31="", W31=""), "", IF(AND(G31=U31, I31=W31), $F$3, IF(G31-I31=U31-W31, $F$4, IF(AND(G31=I31, U31=W31),$F$6, IF(SIGN(G31-I31)=SIGN(U31-W31), $F$5, 0))))) -> 4 | Z31: 4 | AA31: : | AB31: 1 | AC31: 8 | AE31: 3 | AF31: : | AG31: 1 | AH31: =IF(OR(G31="", I31="", AE31="", AG31=""), "", IF(AND(G31=AE31, I31=AG31), $F$3, IF(G31-I31=AE31-AG31, $F$4, IF(AND(G31=I31, AE31=AG31),$F$6, IF(SIGN(G31-I31)=SIGN(AE31-AG31), $F$5, 0))))) -> 4 | AJ31: 3 | AK31: : | AL31: 0 | AM31: =IF(OR(G31="", I31="", AJ31="", AL31=""), "", IF(AND(G31=AJ31, I31=AL31), $F$3, IF(G31-I31=AJ31-AL31, $F$4, IF(AND(G31=I31, AJ31=AL31),$F$6, IF(SIGN(G31-I31)=SIGN(AJ31-AL31), $F$5, 0))))) -> 4 | AO31: 4 | AP31: : | AQ31: 0 | AR31: 8 | AT31: 3 | AU31: : | AV31: 0 | AW31: 8 | AY31: 3 | AZ31: : | BA31: 1 | BB31: 8 | BD31: 3 | BE31: : | BF31: 1 | BG31: 8 | BI31: 3 | BJ31: : | BK31: 1 | BL31: 8 | BN31: 2 | BO31: : | BP31: 0 | BQ31: 4
A32: neděle 9.8. | B32: 0.70833333 | C32: HRADEC KRÁLOVÉ | D32: BANÍK OSTRAVA | G32: 2 | H32: : | I32: 1 | K32: 1 | L32: : | M32: 1 | N32: =IF(OR(G32="", I32="", K32="", M32=""), "", IF(AND(G32=K32, I32=M32), $F$3, IF(G32-I32=K32-M32, $F$4, IF(AND(G32=I32, K32=M32),$F$6, IF(SIGN(G32-I32)=SIGN(K32-M32), $F$5, 0))))) -> 0 | P32: 2 | Q32: : | R32: 0 | S32: =IF(OR(G32="", I32="", P32="", R32=""), "", IF(AND(G32=P32, I32=R32), $F$3, IF(G32-I32=P32-R32, $F$4, IF(AND(G32=I32, P32=R32),$F$6, IF(SIGN(G32-I32)=SIGN(P32-R32), $F$5, 0))))) -> 4 | U32: 1 | V32: : | W32: 0 | X32: 12 | Z32: 2 | AA32: : | AB32: 1 | AC32: =IF(OR(G32="", I32="", Z32="", AB32=""), "", IF(AND(G32=Z32, I32=AB32), $F$3, IF(G32-I32=Z32-AB32, $F$4, IF(AND(G32=I32, Z32=AB32),$F$6, IF(SIGN(G32-I32)=SIGN(Z32-AB32), $F$5, 0))))) -> 15 | AE32: 2 | AF32: : | AG32: 1 | AH32: =IF(OR(G32="", I32="", AE32="", AG32=""), "", IF(AND(G32=AE32, I32=AG32), $F$3, IF(G32-I32=AE32-AG32, $F$4, IF(AND(G32=I32, AE32=AG32),$F$6, IF(SIGN(G32-I32)=SIGN(AE32-AG32), $F$5, 0))))) -> 15 | AJ32: 2 | AK32: : | AL32: 1 | AM32: =IF(OR(G32="", I32="", AJ32="", AL32=""), "", IF(AND(G32=AJ32, I32=AL32), $F$3, IF(G32-I32=AJ32-AL32, $F$4, IF(AND(G32=I32, AJ32=AL32),$F$6, IF(SIGN(G32-I32)=SIGN(AJ32-AL32), $F$5, 0))))) -> 15 | AO32: 2 | AP32: : | AQ32: 1 | AR32: =IF(OR(G32="", I32="", AO32="", AQ32=""), "", IF(AND(G32=AO32, I32=AQ32), $F$3, IF(G32-I32=AO32-AQ32, $F$4, IF(AND(G32=I32, AO32=AQ32),$F$6, IF(SIGN(G32-I32)=SIGN(AO32-AQ32), $F$5, 0))))) -> 15 | AT32: 1 | AU32: : | AV32: 1 | AW32: =IF(OR(G32="", I32="", AT32="", AV32=""), "", IF(AND(G32=AT32, I32=AV32), $F$3, IF(G32-I32=AT32-AV32, $F$4, IF(AND(G32=I32, AT32=AV32),$F$6, IF(SIGN(G32-I32)=SIGN(AT32-AV32), $F$5, 0))))) -> 0 | AY32: 2 | AZ32: : | BA32: 1 | BB32: =IF(OR(G32="", I32="", AY32="", BA32=""), "", IF(AND(G32=AY32, I32=BA32), $F$3, IF(G32-I32=AY32-BA32, $F$4, IF(AND(G32=I32, AY32=BA32),$F$6, IF(SIGN(G32-I32)=SIGN(AY32-BA32), $F$5, 0))))) -> 15 | BD32: 2 | BE32: : | BF32: 0 | BG32: =IF(OR(G32="", I32="", BD32="", BF32=""), "", IF(AND(G32=BD32, I32=BF32), $F$3, IF(G32-I32=BD32-BF32, $F$4, IF(AND(G32=I32, BD32=BF32),$F$6, IF(SIGN(G32-I32)=SIGN(BD32-BF32), $F$5, 0))))) -> 4 | BI32: 2 | BJ32: : | BK32: 0 | BL32: 4 | BN32: 1 | BO32: : | BP32: 1 | BQ32: 0
A33: neděle 9.8. | B33: 0.70833333 | C33: JABLONEC | D33: SLOVÁCKO | G33: 1 | H33: : | I33: 0 | K33: 1 | L33: : | M33: 1 | N33: =IF(OR(G33="", I33="", K33="", M33=""), "", IF(AND(G33=K33, I33=M33), $F$3, IF(G33-I33=K33-M33, $F$4, IF(AND(G33=I33, K33=M33),$F$6, IF(SIGN(G33-I33)=SIGN(K33-M33), $F$5, 0))))) -> 0 | P33: 2 | Q33: : | R33: 1 | S33: 6 | U33: 2 | V33: : | W33: 1 | X33: 6 | Z33: 1 | AA33: : | AB33: 0 | AC33: =IF(OR(G33="", I33="", Z33="", AB33=""), "", IF(AND(G33=Z33, I33=AB33), $F$3, IF(G33-I33=Z33-AB33, $F$4, IF(AND(G33=I33, Z33=AB33),$F$6, IF(SIGN(G33-I33)=SIGN(Z33-AB33), $F$5, 0))))) -> 15 | AE33: 1 | AF33: : | AG33: 1 | AH33: =IF(OR(G33="", I33="", AE33="", AG33=""), "", IF(AND(G33=AE33, I33=AG33), $F$3, IF(G33-I33=AE33-AG33, $F$4, IF(AND(G33=I33, AE33=AG33),$F$6, IF(SIGN(G33-I33)=SIGN(AE33-AG33), $F$5, 0))))) -> 0 | AJ33: 2 | AK33: : | AL33: 1 | AM33: 6 | AO33: 2 | AP33: : | AQ33: 1 | AR33: 6 | AT33: 2 | AU33: : | AV33: 0 | AW33: =IF(OR(G33="", I33="", AT33="", AV33=""), "", IF(AND(G33=AT33, I33=AV33), $F$3, IF(G33-I33=AT33-AV33, $F$4, IF(AND(G33=I33, AT33=AV33),$F$6, IF(SIGN(G33-I33)=SIGN(AT33-AV33), $F$5, 0))))) -> 4 | AY33: 3 | AZ33: : | BA33: 0 | BB33: =IF(OR(G33="", I33="", AY33="", BA33=""), "", IF(AND(G33=AY33, I33=BA33), $F$3, IF(G33-I33=AY33-BA33, $F$4, IF(AND(G33=I33, AY33=BA33),$F$6, IF(SIGN(G33-I33)=SIGN(AY33-BA33), $F$5, 0))))) -> 4 | BD33: 3 | BE33: : | BF33: 1 | BG33: =IF(OR(G33="", I33="", BD33="", BF33=""), "", IF(AND(G33=BD33, I33=BF33), $F$3, IF(G33-I33=BD33-BF33, $F$4, IF(AND(G33=I33, BD33=BF33),$F$6, IF(SIGN(G33-I33)=SIGN(BD33-BF33), $F$5, 0))))) -> 4 | BI33: 2 | BJ33: : | BK33: 1 | BL33: 6 | BN33: 1 | BO33: : | BP33: 0 | BQ33: 15
A34: neděle 9.8. | B34: 0.83333333 | C34: ARTIS BRNO | D34: OLOMOUC | G34: 1 | H34: : | I34: 2 | K34: 0 | L34: : | M34: 2 | N34: =IF(OR(G34="", I34="", K34="", M34=""), "", IF(AND(G34=K34, I34=M34), $F$3, IF(G34-I34=K34-M34, $F$4, IF(AND(G34=I34, K34=M34),$F$6, IF(SIGN(G34-I34)=SIGN(K34-M34), $F$5, 0))))) -> 4 | P34: 1 | Q34: : | R34: 2 | S34: =IF(OR(G34="", I34="", P34="", R34=""), "", IF(AND(G34=P34, I34=R34), $F$3, IF(G34-I34=P34-R34, $F$4, IF(AND(G34=I34, P34=R34),$F$6, IF(SIGN(G34-I34)=SIGN(P34-R34), $F$5, 0))))) -> 15 | U34: 2 | V34: : | W34: 2 | X34: =IF(OR(G34="", I34="", U34="", W34=""), "", IF(AND(G34=U34, I34=W34), $F$3, IF(G34-I34=U34-W34, $F$4, IF(AND(G34=I34, U34=W34),$F$6, IF(SIGN(G34-I34)=SIGN(U34-W34), $F$5, 0))))) -> 0 | Z34: 2 | AA34: : | AB34: 4 | AC34: =IF(OR(G34="", I34="", Z34="", AB34=""), "", IF(AND(G34=Z34, I34=AB34), $F$3, IF(G34-I34=Z34-AB34, $F$4, IF(AND(G34=I34, Z34=AB34),$F$6, IF(SIGN(G34-I34)=SIGN(Z34-AB34), $F$5, 0))))) -> 4 | AE34: 1 | AF34: : | AG34: 1 | AH34: =IF(OR(G34="", I34="", AE34="", AG34=""), "", IF(AND(G34=AE34, I34=AG34), $F$3, IF(G34-I34=AE34-AG34, $F$4, IF(AND(G34=I34, AE34=AG34),$F$6, IF(SIGN(G34-I34)=SIGN(AE34-AG34), $F$5, 0))))) -> 0 | AJ34: 1 | AK34: : | AL34: 3 | AM34: 8 | AO34: 1 | AP34: : | AQ34: 2 | AR34: =IF(OR(G34="", I34="", AO34="", AQ34=""), "", IF(AND(G34=AO34, I34=AQ34), $F$3, IF(G34-I34=AO34-AQ34, $F$4, IF(AND(G34=I34, AO34=AQ34),$F$6, IF(SIGN(G34-I34)=SIGN(AO34-AQ34), $F$5, 0))))) -> 15 | AT34: 1 | AU34: : | AV34: 1 | AW34: =IF(OR(G34="", I34="", AT34="", AV34=""), "", IF(AND(G34=AT34, I34=AV34), $F$3, IF(G34-I34=AT34-AV34, $F$4, IF(AND(G34=I34, AT34=AV34),$F$6, IF(SIGN(G34-I34)=SIGN(AT34-AV34), $F$5, 0))))) -> 0 | AY34: 2 | AZ34: : | BA34: 2 | BB34: =IF(OR(G34="", I34="", AY34="", BA34=""), "", IF(AND(G34=AY34, I34=BA34), $F$3, IF(G34-I34=AY34-BA34, $F$4, IF(AND(G34=I34, AY34=BA34),$F$6, IF(SIGN(G34-I34)=SIGN(AY34-BA34), $F$5, 0))))) -> 0 | BD34: 0 | BE34: : | BF34: 2 | BG34: =IF(OR(G34="", I34="", BD34="", BF34=""), "", IF(AND(G34=BD34, I34=BF34), $F$3, IF(G34-I34=BD34-BF34, $F$4, IF(AND(G34=I34, BD34=BF34),$F$6, IF(SIGN(G34-I34)=SIGN(BD34-BF34), $F$5, 0))))) -> 4 | BI34: 1 | BJ34: : | BK34: 3 | BL34: 4 | BN34: 2 | BO34: : | BP34: 4 | BQ34: 4
A36: sobota 15.8. | B36: 0.70833333 | C36: PARDUBICE | D36: MLADÁ BOLESLAV | E36: 4.KOLO | H36: : | L36: : | N36: =IF(OR(G36="", I36="", K36="", M36=""), "", IF(AND(G36=K36, I36=M36), $F$3, IF(G36-I36=K36-M36, $F$4, IF(AND(G36=I36, K36=M36),$F$6, IF(SIGN(G36-I36)=SIGN(K36-M36), $F$5, 0))))) | Q36: : | S36: =IF(OR(G36="", I36="", P36="", R36=""), "", IF(AND(G36=P36, I36=R36), $F$3, IF(G36-I36=P36-R36, $F$4, IF(AND(G36=I36, P36=R36),$F$6, IF(SIGN(G36-I36)=SIGN(P36-R36), $F$5, 0))))) | V36: : | X36: =IF(OR(G36="", I36="", U36="", W36=""), "", IF(AND(G36=U36, I36=W36), $F$3, IF(G36-I36=U36-W36, $F$4, IF(AND(G36=I36, U36=W36),$F$6, IF(SIGN(G36-I36)=SIGN(U36-W36), $F$5, 0))))) | AA36: : | AC36: =IF(OR(G36="", I36="", Z36="", AB36=""), "", IF(AND(G36=Z36, I36=AB36), $F$3, IF(G36-I36=Z36-AB36, $F$4, IF(AND(G36=I36, Z36=AB36),$F$6, IF(SIGN(G36-I36)=SIGN(Z36-AB36), $F$5, 0))))) | AF36: : | AH36: =IF(OR(G36="", I36="", AE36="", AG36=""), "", IF(AND(G36=AE36, I36=AG36), $F$3, IF(G36-I36=AE36-AG36, $F$4, IF(AND(G36=I36, AE36=AG36),$F$6, IF(SIGN(G36-I36)=SIGN(AE36-AG36), $F$5, 0))))) | AK36: : | AM36: =IF(OR(G36="", I36="", AJ36="", AL36=""), "", IF(AND(G36=AJ36, I36=AL36), $F$3, IF(G36-I36=AJ36-AL36, $F$4, IF(AND(G36=I36, AJ36=AL36),$F$6, IF(SIGN(G36-I36)=SIGN(AJ36-AL36), $F$5, 0))))) | AP36: : | AR36: =IF(OR(G36="", I36="", AO36="", AQ36=""), "", IF(AND(G36=AO36, I36=AQ36), $F$3, IF(G36-I36=AO36-AQ36, $F$4, IF(AND(G36=I36, AO36=AQ36),$F$6, IF(SIGN(G36-I36)=SIGN(AO36-AQ36), $F$5, 0))))) | AU36: : | AW36: =IF(OR(G36="", I36="", AT36="", AV36=""), "", IF(AND(G36=AT36, I36=AV36), $F$3, IF(G36-I36=AT36-AV36, $F$4, IF(AND(G36=I36, AT36=AV36),$F$6, IF(SIGN(G36-I36)=SIGN(AT36-AV36), $F$5, 0))))) | AZ36: : | BB36: =IF(OR(G36="", I36="", AY36="", BA36=""), "", IF(AND(G36=AY36, I36=BA36), $F$3, IF(G36-I36=AY36-BA36, $F$4, IF(AND(G36=I36, AY36=BA36),$F$6, IF(SIGN(G36-I36)=SIGN(AY36-BA36), $F$5, 0))))) | BE36: : | BG36: =IF(OR(G36="", I36="", BD36="", BF36=""), "", IF(AND(G36=BD36, I36=BF36), $F$3, IF(G36-I36=BD36-BF36, $F$4, IF(AND(G36=I36, BD36=BF36),$F$6, IF(SIGN(G36-I36)=SIGN(BD36-BF36), $F$5, 0))))) | BJ36: : | BL36: =IF(OR(L36="", N36="", BI36="", BK36=""), "", IF(AND(L36=BI36, N36=BK36), $F$3, IF(L36-N36=BI36-BK36, $F$4, IF(AND(L36=N36, BI36=BK36),$F$6, IF(SIGN(L36-N36)=SIGN(BI36-BK36), $F$5, 0))))) | BO36: : | BQ36: =IF(OR(Q36="", S36="", BN36="", BP36=""), "", IF(AND(Q36=BN36, S36=BP36), $F$3, IF(Q36-S36=BN36-BP36, $F$4, IF(AND(Q36=S36, BN36=BP36),$F$6, IF(SIGN(Q36-S36)=SIGN(BN36-BP36), $F$5, 0)))))
A37: sobota 15.8. | B37: 0.70833333 | C37: SLOVÁCKO | D37: OLOMOUC | H37: : | L37: : | N37: =IF(OR(G37="", I37="", K37="", M37=""), "", IF(AND(G37=K37, I37=M37), $F$3, IF(G37-I37=K37-M37, $F$4, IF(AND(G37=I37, K37=M37),$F$6, IF(SIGN(G37-I37)=SIGN(K37-M37), $F$5, 0))))) | Q37: : | S37: =IF(OR(G37="", I37="", P37="", R37=""), "", IF(AND(G37=P37, I37=R37), $F$3, IF(G37-I37=P37-R37, $F$4, IF(AND(G37=I37, P37=R37),$F$6, IF(SIGN(G37-I37)=SIGN(P37-R37), $F$5, 0))))) | V37: : | X37: =IF(OR(G37="", I37="", U37="", W37=""), "", IF(AND(G37=U37, I37=W37), $F$3, IF(G37-I37=U37-W37, $F$4, IF(AND(G37=I37, U37=W37),$F$6, IF(SIGN(G37-I37)=SIGN(U37-W37), $F$5, 0))))) | AA37: : | AC37: =IF(OR(G37="", I37="", Z37="", AB37=""), "", IF(AND(G37=Z37, I37=AB37), $F$3, IF(G37-I37=Z37-AB37, $F$4, IF(AND(G37=I37, Z37=AB37),$F$6, IF(SIGN(G37-I37)=SIGN(Z37-AB37), $F$5, 0))))) | AF37: : | AH37: =IF(OR(G37="", I37="", AE37="", AG37=""), "", IF(AND(G37=AE37, I37=AG37), $F$3, IF(G37-I37=AE37-AG37, $F$4, IF(AND(G37=I37, AE37=AG37),$F$6, IF(SIGN(G37-I37)=SIGN(AE37-AG37), $F$5, 0))))) | AK37: : | AM37: =IF(OR(G37="", I37="", AJ37="", AL37=""), "", IF(AND(G37=AJ37, I37=AL37), $F$3, IF(G37-I37=AJ37-AL37, $F$4, IF(AND(G37=I37, AJ37=AL37),$F$6, IF(SIGN(G37-I37)=SIGN(AJ37-AL37), $F$5, 0))))) | AP37: : | AR37: =IF(OR(G37="", I37="", AO37="", AQ37=""), "", IF(AND(G37=AO37, I37=AQ37), $F$3, IF(G37-I37=AO37-AQ37, $F$4, IF(AND(G37=I37, AO37=AQ37),$F$6, IF(SIGN(G37-I37)=SIGN(AO37-AQ37), $F$5, 0))))) | AU37: : | AW37: =IF(OR(G37="", I37="", AT37="", AV37=""), "", IF(AND(G37=AT37, I37=AV37), $F$3, IF(G37-I37=AT37-AV37, $F$4, IF(AND(G37=I37, AT37=AV37),$F$6, IF(SIGN(G37-I37)=SIGN(AT37-AV37), $F$5, 0))))) | AZ37: : | BB37: =IF(OR(G37="", I37="", AY37="", BA37=""), "", IF(AND(G37=AY37, I37=BA37), $F$3, IF(G37-I37=AY37-BA37, $F$4, IF(AND(G37=I37, AY37=BA37),$F$6, IF(SIGN(G37-I37)=SIGN(AY37-BA37), $F$5, 0))))) | BE37: : | BG37: =IF(OR(G37="", I37="", BD37="", BF37=""), "", IF(AND(G37=BD37, I37=BF37), $F$3, IF(G37-I37=BD37-BF37, $F$4, IF(AND(G37=I37, BD37=BF37),$F$6, IF(SIGN(G37-I37)=SIGN(BD37-BF37), $F$5, 0))))) | BJ37: : | BL37: =IF(OR(L37="", N37="", BI37="", BK37=""), "", IF(AND(L37=BI37, N37=BK37), $F$3, IF(L37-N37=BI37-BK37, $F$4, IF(AND(L37=N37, BI37=BK37),$F$6, IF(SIGN(L37-N37)=SIGN(BI37-BK37), $F$5, 0))))) | BO37: : | BQ37: =IF(OR(Q37="", S37="", BN37="", BP37=""), "", IF(AND(Q37=BN37, S37=BP37), $F$3, IF(Q37-S37=BN37-BP37, $F$4, IF(AND(Q37=S37, BN37=BP37),$F$6, IF(SIGN(Q37-S37)=SIGN(BN37-BP37), $F$5, 0)))))
